Workbook

Sheet README
A1: JCSC CAMPAIGN ASSESSMENT – WORKBOOK GUIDE
A2: WORKBOOK STRUCTURE
A3: PMESII-ASCOPE: Assign provisional labels via dropdowns (cols B,D,F,H,J,L).
A4: PMESII Labels: Auto-compiled by label type from full PMESII-ASCOPE sheet. Read-only.
A5: 3CF Factor Analysis: Label conclusions in col F (dropdown). Text in col G.
A6: Master Factors: Assign MSO/OO/DC numbers via dropdowns. Conclusions auto-pull.
A7: Synch Matrix: MASTER = full grid. SHRUNK = auto-filters to populated rows.
A9: PROTECTION
A10: Password: password
A11: Only input cells editable: label dropdowns, conclusion text, assignment dropdowns.
A13: COLOURS
A14: PMESII-ASCOPE: one background colour per PMESII dimension.
... A16: Synch Matrix: MSO rows=dark navy, OO rows=mid blue, DC rows=light blue.

Sheet ASCOPE_PMESII
A1: PMESII / ASCOPE OPERATIONAL ENVIRONMENT ASSESSMENT
A2: PMESII | B2: Prov. Label | C2: AREAS Where? | D2: Prov. Label | E2: STRUCTURES Why? | F2: Prov. Label | G2: CAPABILITIES Who? | H2: Prov. Label | I2: ORGANISATIONS What? | J2: Prov. Label | K2: PEOPLE How? | L2: Prov. Label | M2: EVENTS When? | O2: Label Options
A3: POLITICAL / GOVERNANCE | B3: CV | C3: Jakarta authority has collapsed across N Sumatra | D3: CC | E3: KODAM 1 HQ MEDAN anchors IRS governance | F3: CC | G3: GoIND retains legal sovereignty and external recognition | H3: CV | I3: IRS, GoIND, ISIL/JI and regional states diverge | J3: CV | K3: Anti-Java grievance predates the coup | L3: CV | M3: IRS seeks recognition before GoIND can respond | O3: MSO
B4: CV | C4: IRS control creates secession contagion risk | D4: CV | E4: MEDAN control gives IRS state-like appearance | F4: CV | G4: GoIND lacks local force density in rebel provinces | H4: CV | I4: IRS coalition contains incompatible political factions | J4: CV | K4: Population separates sovereignty from Java dominance | L4: CV | M4: Time hardens rebel governance and normalises tariffs | O4: OO
B5: COR | C5: Support GoIND sovereignty without Java-centric framing | D5: COR | E5: Separate rebel command from civil administration | F5: COR | G5: Enable GoIND entry through secured XPOD | H5: COR | I5: Exploit faction seams without rejecting Sumatran grievance | J5: COR | K5: Acknowledge grievance while rejecting secession | L5: COR | M5: Deny early IRS diplomatic normalisation | O5: DC
B6: CC | C6: ACEH defence is political as well as military | D6: CV | E6: Provincial offices give IRS coercive legitimacy | F6: CR | G6: Coalition lift and protection enable GoIND re-entry | H6: CR | I6: Regional partners needed for access and legitimacy | J6: CR | K6: Trusted local voices more credible than NATO | L6: CR | M6: Rapid warning order to access decision sequence | O6: OE
B7: CR | C7: GoIND consent enables NATO legitimacy | D7: CR | E7: GoIND administrators required behind entry force | F7: CV | G7: Weak GoIND capacity invites NATO substitution | H7: RISK | I7: Blunt targeting can unify anti-NATO actors | J7: RISK | K7: Civilian harm restores Hasan authority | L7: RISK | M7: Delay increases force requirement and casualties | O7: OA
B8: RISK | C8: Heavy NATO footprint can validate IRS narrative | D8: RISK | E8: Empty offices after clearance create governance vacuum | F8: RISK | G8: NATO overreach undermines GoIND legitimacy | H8: CC | I8: ASEAN states shape consent and perception | J8: CC | K8: Hasan's charisma holds disparate factions together | L8: CC | M8: Aceh offensive likely before NATO mass arrives | O8: RISK
B9: KCD-MUST | C9: NATO must restore territorial integrity, not occupy Sumatra | D9: KCD-MUST | E9: Civil authority must follow security success immediately | F9: KCD-MUST | G9: GoIND must be face of restored authority | H9: KCD-MUST | I9: Engage Malaysia/Singapore before visible escalation | J9: KCD-MUST | K9: Discredit Hasan without insulting Sumatrans | L9: KCD-MUST | M9: Move before IRS creates irreversible facts | O9: CV
B10: KCD-SHOULD | C10: Support visible GoIND lead at secured nodes | D10: KCD-SHOULD | E10: Prioritise MEDAN-BELAWAN political infrastructure | F10: KCD-SHOULD | G10: Use NATO to enable, not replace, governance | H10: KCD-SHOULD | I10: Segment IRS nationalists from terrorist actors | J10: KCD-SHOULD | K10: Expose Razil corruption and criminal patronage | L10: KCD-SHOULD | M10: Publicly link operation to lawful restoration | O10: COR
B11: KCD-CANNOT | C11: Cannot treat Sumatra as uniform political terrain | D11: KCD-CANNOT | E11: Cannot measure success by terrain alone | F11: KCD-CANNOT | G11: Cannot rebuild sovereignty by NATO-only action | H11: KCD-CANNOT | I11: Cannot use one political message for all actors | J11: KCD-CANNOT | K11: Cannot conflate civilians with IRS supporters | L11: KCD-CANNOT | M11: Cannot wait for perfect understanding | O11: REQT
B12: DC | C12: GoIND authority is STABILISED | D12: DC | E12: MEDAN-BELAWAN ISOLATED | F12: DC | G12: GoIND entry force in SUMATRA is PROTECTED | H12: OE | I12: MANIPULATE IRS coalition | J12: DC | K12: HASAN is DISCREDITED | L12: DECISION | M12: COM needs early political risk tolerance | O12: REST
A13: MILITARY / SECURITY | B13: CV | C13: Sumatra terrain favours defence and guerrilla delay | D13: CC | E13: IRS holds air bases, naval bases and CDCM sites | F13: CC | G13: IRS fields 78k troops, subs, mines, SAMs, CDCMs | H13: CC | I13: KODAM 1 integrates land, sea and air operations | J13: CC | K13: 95 percent of KODAM 1 shifted loyalty | L13: CC | M13: Aceh offensive likely uses three phases | O13: KCD-MUST
B14: CV | C14: 75 percent hinders cross-country manoeuvre | D14: CV | E14: BELAWAN, MEDAN and DUMAI enable joint defence | F14: CV | G14: Capability is broad but shallow and older | H14: CV | I14: KODAM 1 loyalty is Hasan-dependent | J14: CV | K14: Loyalty is ethnic, personal and momentum-based | L14: CV | M14: Recon, barrage and amphibious fixing create warning | O14: KCD-SHOULD
B15: COR | C15: Ground entry must be airmobile and maritime-enabled | D15: COR | E15: Sequence ISR, SEAD, MCM and port clearance | F15: COR | G15: Attack the joint kill chain, not just launchers | H15: COR | I15: Separate commanders from Hasan's authority | J15: COR | K15: Offer protected off-ramps below senior leadership | L15: COR | M15: Trigger points must cue pre-emptive interdiction | O15: KCD-SHOULD NOT
B16: CR | C16: Main roads, bridges and APOD/SPOD decide reach | D16: CR | E16: Airbases and radars must be suppressed or controlled | F16: CR | G16: MCM, ASW, SEAD, EW and ISR required | H16: CR | I16: J2/J3 targeting must map command relationships | J16: CR | K16: HUMINT/SIGINT needed on faction morale | L16: CR | M16: Indications: artillery, staging, naval sorties, bridging | O16: KCD-CANNOT
B17: RISK | C17: Ambush and IED threat rises off main routes | D17: RISK | E17: Undegraded A2/AD makes entry politically costly | F17: RISK | G17: Single ship loss can fracture NATO will | H17: RISK | I17: Decapitation without succession analysis may backfire | J17: RISK | K17: Collective punishment strengthens military cohesion | L17: RISK | M17: Late response lets IRS seize energy infrastructure | O17: DECISION
B18: CC | C18: Aceh approaches are decisive to rebel expansion | D18: CC | E18: Bridges and MSRs are operational choke points | F18: CV | G18: Limited night capability gives temporal advantage | H18: CV | I18: Razil corruption and Ahmad competence create seams | J18: CV | K18: Territorial reservists less reliable outside home areas | L18: CC | M18: CDCM/mining action can precede open attack | O18: ASSUMPTION
B19: KCD-MUST | C19: Secure entry nodes before inland manoeuvre | D19: KCD-MUST | E19: Disrupt A2/AD before high-signature entry | F19: KCD-MUST | G19: Use darkness, EW and ISR to unhinge IRS | H19: KCD-MUST | I19: Exploit leadership fractures before decisive engagement | J19: KCD-MUST | K19: Separate regular cadre from local militia | L19: KCD-MUST | M19: Block offensive before Langsa defence collapses | O19: CONSTRAINT
B20: KCD-SHOULD | C20: Avoid broad sweep through hostile terrain | D20: KCD-SHOULD | E20: Isolate bases rather than clear every position | F20: KCD-SHOULD | G20: Target sensors, C2 and sustainment first | H20: KCD-SHOULD | I20: Protect defections and surrender channels | J20: KCD-SHOULD | K20: Target orders, pay, family and amnesty channels | L20: KCD-SHOULD | M20: Prepare branches for MLCOA and MDCOA | O20: LIMITATION
B21: KCD-CANNOT | C21: Cannot assume mechanised tempo inland | D21: KCD-CANNOT | E21: Cannot expose shipping to uncleared CDCM arcs | F21: KCD-CANNOT | G21: Cannot defeat IRS by land attrition alone | H21: KCD-CANNOT | I21: Cannot assume KODAM 1 collapses uniformly | J21: KCD-CANNOT | K21: Cannot assume all rebel troops are ideological | L21: KCD-CANNOT | M21: Cannot treat naval patrols as routine policing | O21: CC
B22: DC | C22: IRS expansion is BLOCKED | D22: DC | E22: IRS integrated A2/AD system DISRUPTED | F22: OA | G22: ATTACK mines, CDCMs, submarines, radar and air-defence nodes | H22: OE | I22: UNDERMINE IRS in MEDAN-BELAWAN | J22: OE | K22: DISRUPT cohesion | L22: DECISION | M22: IRS crossing Aceh LD or mining Malacca | O22: CR
A23: ECONOMIC | B23: CC | C23: Sumatra holds critical oil, LNG and export base | D23: CC | E23: Ports, refineries, LNG plant and pipelines are dual-use | F23: CC | G23: IRS merchant fleet sustains external trade | H23: CV | I23: TCOs, NK and Chinese-linked actors support IRS | J23: CV | K23: Local livelihoods depend on ports, energy and fishing | L23: CV | M23: Every export cycle normalises IRS statehood | O23: PCS
B24: CV | C24: IRS economy depends on east-coast maritime access | D24: CV | E24: Same nodes fund IRS and enable GoIND recovery | F24: CV | G24: Export economy vulnerable to tracking and interdiction | H24: CV | I24: External finance reduces pressure on Hasan | J24: CV | K24: Economic hardship can shift civilians toward IRS | L24: CV | M24: Market shock can precede tactical effect
B25: COR | C25: Control revenue areas without destroying production | D25: COR | E25: Use graduated interdiction and seizure sequencing | F25: COR | G25: Monitor, board, divert and evidence coercive trade | H25: COR | I25: Map brokers, shippers, insurers and intermediaries | J25: COR | K25: Protect wages, food, fuel and essential services | L25: COR | M25: Pre-empt tariff announcements and port seizures
B26: CR | C26: BELAWAN-DUMAI-POL corridor must be mapped | D26: CR | E26: Legal, engineer and energy expertise required | F26: CR | G26: Maritime legal authority and shipping liaison required | H26: CR | I26: Treasury, law-enforcement and partner intelligence required | J26: CR | K26: Civil-military economic cell required early | L26: CR | M26: Shipping advisory and sanctions packages required
B27: RISK | C27: Economic paralysis harms GoIND and civilians | D27: RISK | E27: Strike damage can delay strategic end state | F27: RISK | G27: Wrongful interference damages coalition legitimacy | H27: RISK | I27: Attribution gaps create diplomatic friction | J27: RISK | K27: Revenue denial without relief creates resentment | L27: RISK | M27: Insurance reaction may close trade beyond JOA
B28: CC | C28: Strait tariffs convert coercion into cash | D28: CV | E28: Electrical grid vulnerability cuts both ways | F28: CV | G28: Money networks link criminal and external sponsors | H28: CC | I28: Private companies hold key transactional data | J28: CC | K28: Workers can enable sabotage or continuity | L28: CC | M28: Energy disruption affects NATO member interests
B29: KCD-MUST | C29: Deny IRS revenue while preserving GoIND assets | D29: KCD-MUST | E29: Protect critical energy infrastructure from sabotage | F29: KCD-MUST | G29: Fuse finance, maritime and intelligence targeting | H29: KCD-MUST | I29: Use non-military instruments against finance flows | J29: KCD-MUST | K29: Separate IRS revenue from civilian survival | L29: KCD-MUST | M29: Control economic narrative before coercive tariffs bite
B30: KCD-SHOULD | C30: Target coercive export mechanisms, not livelihoods | D30: KCD-SHOULD | E30: Capture records, terminals and control systems intact | F30: KCD-SHOULD | G30: Exploit insurance, port and charter data | H30: KCD-SHOULD | I30: Expose sponsor links to undermine recognition bid | J30: KCD-SHOULD | K30: Preserve energy workforce and technical management | L30: KCD-SHOULD | M30: Synchronise interdiction with public legal explanation
B31: KCD-CANNOT | C31: Cannot blockade without humanitarian and legal effects | D31: KCD-CANNOT | E31: Cannot treat POL/LNG as purely military target | F31: KCD-CANNOT | G31: Cannot interdict finance with kinetic tools alone | H31: KCD-CANNOT | I31: Cannot assume sponsorship is centrally directed | J31: KCD-CANNOT | K31: Cannot win population through economic strangulation | L31: KCD-CANNOT | M31: Cannot allow IRS to sell stability-for-recognition
B32: DC | C32: MEDAN-BELAWAN ISOLATED | D32: DC | E32: Priority governance / infrastructure nodes are SECURED | F32: OA | G32: INTERDICT POL/LNG export, tariff collection and coercive maritime enforcement | H32: DC | I32: North Korean / Chinese-linked support networks are INTERDICTED | J32: OE | K32: STABILISE essential services | L32: DECISION | M32: COM needs economic target tolerance guidance
A33: SOCIAL | B33: CV | C33: Sumatra is ethnically and culturally segmented | D33: CC | E33: Medan and port cities are social control hubs | F33: CV | G33: Foreign nationals create hostage leverage | H33: CV | I33: IRS umbrella mixes nationalists, Islamists and liberals | J33: CV | K33: Civilians distinguish protection from occupation | L33: CV | M33: Refugee flow likely across straits and region
B34: CV | C34: Aceh, Batak, Minangkabau, Malay and Lampung differ | D34: CV | E34: Urban fighting creates immediate legitimacy costs | F34: CV | G34: Civil services degraded under rebel control | H34: CV | I34: ISIL/JI presence contaminates IRS legitimacy | J34: CV | K34: Families influence rebel morale and defection | L34: CV | M34: IRS abuses and ethnic violence trigger HA demand
B35: COR | C35: Segment engagement by province and culture | D35: COR | E35: Isolate armed actors before urban clearance | F35: COR | G35: Identify vulnerable groups and essential service gaps | H35: COR | I35: Separate nationalist grievance from terrorist exploitation | J35: COR | K35: Use amnesty, family and livelihood messaging | L35: COR | M35: Secure humanitarian corridors and reception nodes
B36: CR | C36: Cultural advisers and local language support required | D36: CR | E36: Police, civil admin and humanitarian access required | F36: CR | G36: Consular, medical, police and HA liaison required | H36: CR | I36: Engagement map by group, tribe and interest | J36: CR | K36: HUMINT and civil affairs networks required | L36: CR | M36: IDP tracking, medical and camp coordination required
B37: RISK | C37: One-size messaging alienates key audiences | D37: RISK | E37: Urban destruction becomes IRS proof narrative | F37: RISK | G37: Hostage or atrocity event drives political shock | H37: RISK | I37: Over-broad terror label unifies local opposition | J37: RISK | K37: Civilian casualties negate tactical success | L37: RISK | M37: HA failure becomes NATO legitimacy failure
B38: CC | C38: Urban/coastal populations shape perceived legitimacy | D38: CC | E38: Mosques, unions and families shape mobilisation | F38: CC | G38: OCHA and NGOs present in wider response space | H38: CC | I38: Religious and community leaders influence compliance | J38: CC | K38: NATO publics demand restraint and nationals' safety | L38: CC | M38: Atrocity rumours can move populations faster than facts
B39: KCD-MUST | C39: Treat identity as operational terrain | D39: KCD-MUST | E39: Use local intermediaries before kinetic action | F39: KCD-MUST | G39: Protect nationals and civilians in parallel | H39: KCD-MUST | I39: Exploit internal contradictions without insulting identity | J39: KCD-MUST | K39: Make protection visible and measurable | L39: KCD-MUST | M39: Pre-plan civilian harm response before operations
B40: KCD-SHOULD | C40: Prioritise Medan, Aceh and energy communities | D40: KCD-SHOULD | E40: Protect civil structures and public services | F40: KCD-SHOULD | G40: Use HA actors for needs picture, not cover | H40: KCD-SHOULD | I40: Empower non-violent Sumatran interlocutors | J40: KCD-SHOULD | K40: Publish restraint and evidence quickly | L40: KCD-SHOULD | M40: Use evidence capture at first contact
...

Sheet ASCOPE_PMESII Labels
A1: PMESII/ASCOPE PROVISIONAL LABELS – AUTO-COMPILED BY LABEL TYPE
A2: One column per label type. Pulls from all 6 ASCOPE label columns, full sheet range. Updates on label change.
A3: OE | B3: OA | C3: RISK | D3: CV | E3: COR | F3: REQT | G3: REST | H3: KCD-MUST | I3: KCD-SHOULD | J3: KCD-SHOULD NOT | K3: KCD-CANNOT | L3: DECISION | M3: ASSUMPTION | N3: CONSTRAINT | O3: LIMITATION | P3: CC | Q3: CR | R3: PCS
A4: {=IFERROR(IF(1<=COUNTIF(ASCOPE_PMESII!$B$3:$B$62,"OE"),IFERROR(INDEX(ASCOPE_PMESII!$C$3:$C$62,_xlfn.AGGREGATE(15,6,(ROW(ASCOPE_PMESII!$B$3:$B$62)-ROW(ASCOPE_PMESII!$B$3)+1)/(ASCOPE_PMESII!$B$3:$B$62="OE"),1)),""),IF(1<=(COUNTIF(ASCOPE_PMESII!$B$3:$B$62,"OE")+COUNTIF(ASCOPE_PMESII!$D$3:$D$62,"OE")),IFERROR(INDEX(ASCOPE_PMESII!$E$3:$E$62,_xlfn.AGGREGATE(15,6,(ROW(ASCOPE_PMESII!$D$3:$D$62)-ROW(ASCOPE_PMESII!$D$3)+1)/(ASCOPE_PMESII!$D$3:$D$62="OE"),1-(COUNTIF(ASCOPE_PMESII!$B$3:$B$62,"OE")))),""),IF(1<=(COUNTIF(ASCOPE_PMESII!$B$3:$B$62,"OE")+COUNTIF(ASCOPE_PMESII!$D$3:$D$62,"OE")+COUNTIF(ASCOPE_PMESII!$F$3:$F$62,"OE")),IFERROR(INDEX(ASCOPE_PMESII!$G$3:$G$62,_xlfn.AGGREGATE(15,6,(ROW(ASCOPE_PMESII!$F$3:$F$62)-ROW(ASCOPE_PMESII!$F$3)+1)/(ASCOPE_PMESII!$F$3:$F$62="OE"),1-(COUNTIF(ASCOPE_PMESII!$B$3:$B$62,"OE")+COUNTIF(ASCOPE_PMESII!$D$3:$D$62,"OE")))),""),IF(1<=(COUNTIF(ASCOPE_PMESII!$B$3:$B$62,"OE")+COUNTIF(ASCOPE_PMESII!$D$3:$D$62,"OE")+COUNTIF(ASCOPE_PMESII!$F$3:$F$62,"OE")+COUNTIF(ASCOPE_PMESII!$H$3:$H$62,"OE")),IFERROR(INDEX(ASCOPE_PMESII!$I$3:$I$62,_xlfn.AGGREGATE(15,6,(ROW(ASCOPE_PMESII!$H$3:$H$62)-ROW(ASCOPE_PMESII!$H$3)+1)/(ASCOPE_PMESII!$H$3:$H$62="OE"),1-(COUNTIF(ASCOPE_PMESII!$B$3:$B$62,"OE")+COUNTIF(ASCOPE_PMESII!$D$3:$D$62,"OE")+COUNTIF(ASCOPE_PMESII!$F$3:$F$62,"OE")))),""),IF(1<=(COUNTIF(ASCOPE_PMESII!$B$3:$B$62,"OE")+COUNTIF(ASCOPE_PMESII!$D$3:$D$62,"OE")+COUNTIF(ASCOPE_PMESII!$F$3:$F$62,"OE")+COUNTIF(ASCOPE_PMESII!$H$3:$H$62,"OE")+COUNTIF(ASCOPE_PMESII!$J$3:$J$62,"OE")),IFERROR(INDEX(ASCOPE_PMESII!$K$3:$K$62,_xlfn.AGGREGATE(15,6,(ROW(ASCOPE_PMESII!$J$3:$J$62)-ROW(ASCOPE_PMESII!$J$3)+1)/(ASCOPE_PMESII!$J$3:$J$62="OE"),1-(COUNTIF(ASCOPE_PMESII!$B$3:$B$62,"OE")+COUNTIF(ASCOPE_PMESII!$D$3:$D$62,"OE")+COUNTIF(ASCOPE_PMESII!$F$3:$F$62,"OE")+COUNTIF(ASCOPE_PMESII!$H$3:$H$62,"OE")))),""),IFERROR(INDEX(ASCOPE_PMESII!$M$3:$M$62,_xlfn.AGGREGATE(15,6,(ROW(ASCOPE_PMESII!$L$3:$L$62)-ROW(ASCOPE_PMESII!$L$3)+1)/(ASCOPE_PMESII!$L$3:$L$62="OE"),1-(COUNTIF(ASCOPE_PMESII!$B$3:$B$62,"OE")+COUNTIF(ASCOPE_PMESII!$D$3:$D$62,"OE")+COUNTIF(ASCOPE_PMESII!$F$3:$F$62,"OE")+COUNTIF(ASCOPE_PMESII!$H$3:$H$62,"OE")+COUNTIF(ASCOPE_PMESII!$J$3:$J$62,"OE")))),"")))))),"")} -> INFLUENCE key audiences | B4: {=IFERROR(IF(1<=COUNTIF(ASCOPE_PMESII!$B$3:$B$62,"OA"),IFERROR(INDEX(ASCOPE_PMESII!$C$3:$C$62,_xlfn.AGGREGATE(15,6,(ROW(ASCOPE_PMESII!$B$3:$B$62)-ROW(ASCOPE_PMESII!$B$3)+1)/(ASCOPE_PMESII!$B$3:$B$62="OA"),1)),""),IF(1<=(COUNTIF(ASCOPE_PMESII!$B$3:$B$62,"OA")+COUNTIF(ASCOPE_PMESII!$D$3:$D$62,"OA")),IFERROR(INDEX(ASCOPE_PMESII!$E$3:$E$62,_xlfn.AGGREGATE(15,6,(ROW(ASCOPE_PMESII!$D$3:$D$62)-ROW(ASCOPE_PMESII!$D$3)+1)/(ASCOPE_PMESII!$D$3:$D$62="OA"),1-(COUNTIF(ASCOPE_PMESII!$B$3:$B$62,"OA")))),""),IF(1<=(COUNTIF(ASCOPE_PMESII!$B$3:$B$62,"OA")+COUNTIF(ASCOPE_PMESII!$D$3:$D$62,"OA")+COUNTIF(ASCOPE_PMESII!$F$3:$F$62,"OA")),IFERROR(INDEX(ASCOPE_PMESII!$G$3:$G$62,_xlfn.AGGREGATE(15,6,(ROW(ASCOPE_PMESII!$F$3:$F$62)-ROW(ASCOPE_PMESII!$F$3)+1)/(ASCOPE_PMESII!$F$3:$F$62="OA"),1-(COUNTIF(ASCOPE_PMESII!$B$3:$B$62,"OA")+COUNTIF(ASCOPE_PMESII!$D$3:$D$62,"OA")))),""),IF(1<=(COUNTIF(ASCOPE_PMESII!$B$3:$B$62,"OA")+COUNTIF(ASCOPE_PMESII!$D$3:$D$62,"OA")+COUNTIF(ASCOPE_PMESII!$F$3:$F$62,"OA")+COUNTIF(ASCOPE_PMESII!$H$3:$H$62,"OA")),IFERROR(INDEX(ASCOPE_PMESII!$I$3:$I$62,_xlfn.AGGREGATE(15,6,(ROW(ASCOPE_PMESII!$H$3:$H$62)-ROW(ASCOPE_PMESII!$H$3)+1)/(ASCOPE_PMESII!$H$3:$H$62="OA"),1-(COUNTIF(ASCOPE_PMESII!$B$3:$B$62,"OA")+COUNTIF(ASCOPE_PMESII!$D$3:$D$62,"OA")+COUNTIF(ASCOPE_PMESII!$F$3:$F$62,"OA")))),""),IF(1<=(COUNTIF(ASCOPE_PMESII!$B$3:$B$62,"OA")+COUNTIF(ASCOPE_PMESII!$D$3:$D$62,"OA")+COUNTIF(ASCOPE_PMESII!$F$3:$F$62,"OA")+COUNTIF(ASCOPE_PMESII!$H$3:$H$62,"OA")+COUNTIF(ASCOPE_PMESII!$J$3:$J$62,"OA")),IFERROR(INDEX(ASCOPE_PMESII!$K$3:$K$62,_xlfn.AGGREGATE(15,6,(ROW(ASCOPE_PMESII!$J$3:$J$62)-ROW(ASCOPE_PMESII!$J$3)+1)/(ASCOPE_PMESII!$J$3:$J$62="OA"),1-(COUNTIF(ASCOPE_PMESII!$B$3:$B$62,"OA")+COUNTIF(ASCOPE_PMESII!$D$3:$D$62,"OA")+COUNTIF(ASCOPE_PMESII!$F$3:$F$62,"OA")+COUNTIF(ASCOPE_PMESII!$H$3:$H$62,"OA")))),""),IFERROR(INDEX(ASCOPE_PMESII!$M$3:$M$62,_xlfn.AGGREGATE(15,6,(ROW(ASCOPE_PMESII!$L$3:$L$62)-ROW(ASCOPE_PMESII!$L$3)+1)/(ASCOPE_PMESII!$L$3:$L$62="OA"),1-(COUNTIF(ASCOPE_PMESII!$B$3:$B$62,"OA")+COUNTIF(ASCOPE_PMESII!$D$3:$D$62,"OA")+COUNTIF(ASCOPE_PMESII!$F$3:$F$62,"OA")+COUNTIF(ASCOPE_PMESII!$H$3:$H$62,"OA")+COUNTIF(ASCOPE_PMESII!$J$3:$J$62,"OA")))),"")))))),"")} -> ESCORT police, civil administration, port and energy authorities | C4: {=IFERROR(IF(1<=COUNTIF(ASCOPE_PMESII!$B$3:$B$62,"RISK"),IFERROR(INDEX(ASCOPE_PMESII!$C$3:$C$62,_xlfn.AGGREGATE(15,6,(ROW(ASCOPE_PMESII!$B$3:$B$62)-ROW(ASCOPE_PMESII!$B$3)+1)/(ASCOPE_PMESII!$B$3:$B$62="RISK"),1)),""),IF(1<=(COUNTIF(ASCOPE_PMESII!$B$3:$B$62,"RISK")+COUNTIF(ASCOPE_PMESII!$D$3:$D$62,"RISK")),IFERROR(INDEX(ASCOPE_PMESII!$E$3:$E$62,_xlfn.AGGREGATE(15,6,(ROW(ASCOPE_PMESII!$D$3:$D$62)-ROW(ASCOPE_PMESII!$D$3)+1)/(ASCOPE_PMESII!$D$3:$D$62="RISK"),1-(COUNTIF(ASCOPE_PMESII!$B$3:$B$62,"RISK")))),""),IF(1<=(COUNTIF(ASCOPE_PMESII!$B$3:$B$62,"RISK")+COUNTIF(ASCOPE_PMESII!$D$3:$D$62,"RISK")+COUNTIF(ASCOPE_PMESII!$F$3:$F$62,"RISK")),IFERROR(INDEX(ASCOPE_PMESII!$G$3:$G$62,_xlfn.AGGREGATE(15,6,(ROW(ASCOPE_PMESII!$F$3:$F$62)-ROW(ASCOPE_PMESII!$F$3)+1)/(ASCOPE_PMESII!$F$3:$F$62="RISK"),1-(COUNTIF(ASCOPE_PMESII!$B$3:$B$62,"RISK")+COUNTIF(ASCOPE_PMESII!$D$3:$D$62,"RISK")))),""),IF(1<=(COUNTIF(ASCOPE_PMESII!$B$3:$B$62,"RISK")+COUNTIF(ASCOPE_PMESII!$D$3:$D$62,"RISK")+COUNTIF(ASCOPE_PMESII!$F$3:$F$62,"RISK")+COUNTIF(ASCOPE_PMESII!$H$3:$H$62,"RISK")),IFERROR(INDEX(ASCOPE_PMESII!$I$3:$I$62,_xlfn.AGGREGATE(15,6,(ROW(ASCOPE_PMESII!$H$3:$H$62)-ROW(ASCOPE_PMESII!$H$3)+1)/(ASCOPE_PMESII!$H$3:$H$62="RISK"),1-(COUNTIF(ASCOPE_PMESII!$B$3:$B$62,"RISK")+COUNTIF(ASCOPE_PMESII!$D$3:$D$62,"RISK")+COUNTIF(ASCOPE_PMESII!$F$3:$F$62,"RISK")))),""),IF(1<=(COUNTIF(ASCOPE_PMESII!$B$3:$B$62,"RISK")+COUNTIF(ASCOPE_PMESII!$D$3:$D$62,"RISK")+COUNTIF(ASCOPE_PMESII!$F$3:$F$62,"RISK")+COUNTIF(ASCOPE_PMESII!$H$3:$H$62,"RISK")+COUNTIF(ASCOPE_PMESII!$J$3:$J$62,"RISK")),IFERROR(INDEX(ASCOPE_PMESII!$K$3:$K$62,_xlfn.AGGREGATE(15,6,(ROW(ASCOPE_PMESII!$J$3:$J$62)-ROW(ASCOPE_PMESII!$J$3)+1)/(ASCOPE_PMESII!$J$3:$J$62="RISK"),1-(COUNTIF(ASCOPE_PMESII!$B$3:$B$62,"RISK")+COUNTIF(ASCOPE_PMESII!$D$3:$D$62,"RISK")+COUNTIF(ASCOPE_PMESII!$F$3:$F$62,"RISK")+COUNTIF(ASCOPE_PMESII!$H$3:$H$62,"RISK")))),""),IFERROR(INDEX(ASCOPE_PMESII!$M$3:$M$62,_xlfn.AGGREGATE(15,6,(ROW(ASCOPE_PMESII!$L$3:$L$62)-ROW(ASCOPE_PMESII!$L$3)+1)/(ASCOPE_PMESII!$L$3:$L$62="RISK"),1-(COUNTIF(ASCOPE_PMESII!$B$3:$B$62,"RISK")+COUNTIF(ASCOPE_PMESII!$D$3:$D$62,"RISK")+COUNTIF(ASCOPE_PMESII!$F$3:$F$62,"RISK")+COUNTIF(ASCOPE_PMESII!$H$3:$H$62,"RISK")+COUNTIF(ASCOPE_PMESII!$J$3:$J$62,"RISK")))),"")))))),"")} -> Heavy NATO footprint can validate IRS narrative | D4: {=IFERROR(IF(1<=COUNTIF(ASCOPE_PMESII!$B$3:$B$62,"CV"),IFERROR(INDEX(ASCOPE_PMESII!$C$3:$C$62,_xlfn.AGGREGATE(15,6,(ROW(ASCOPE_PMESII!$B$3:$B$62)-ROW(ASCOPE_PMESII!$B$3)+1)/(ASCOPE_PMESII!$B$3:$B$62="CV"),1)),""),IF(1<=(COUNTIF(ASCOPE_PMESII!$B$3:$B$62,"CV")+COUNTIF(ASCOPE_PMESII!$D$3:$D$62,"CV")),IFERROR(INDEX(ASCOPE_PMESII!$E$3:$E$62,_xlfn.AGGREGATE(15,6,(ROW(ASCOPE_PMESII!$D$3:$D$62)-ROW(ASCOPE_PMESII!$D$3)+1)/(ASCOPE_PMESII!$D$3:$D$62="CV"),1-(COUNTIF(ASCOPE_PMESII!$B$3:$B$62,"CV")))),""),IF(1<=(COUNTIF(ASCOPE_PMESII!$B$3:$B$62,"CV")+COUNTIF(ASCOPE_PMESII!$D$3:$D$62,"CV")+COUNTIF(ASCOPE_PMESII!$F$3:$F$62,"CV")),IFERROR(INDEX(ASCOPE_PMESII!$G$3:$G$62,_xlfn.AGGREGATE(15,6,(ROW(ASCOPE_PMESII!$F$3:$F$62)-ROW(ASCOPE_PMESII!$F$3)+1)/(ASCOPE_PMESII!$F$3:$F$62="CV"),1-(COUNTIF(ASCOPE_PMESII!$B$3:$B$62,"CV")+COUNTIF(ASCOPE_PMESII!$D$3:$D$62,"CV")))),""),IF(1<=(COUNTIF(ASCOPE_PMESII!$B$3:$B$62,"CV")+COUNTIF(ASCOPE_PMESII!$D$3:$D$62,"CV")+COUNTIF(ASCOPE_PMESII!$F$3:$F$62,"CV")+COUNTIF(ASCOPE_PMESII!$H$3:$H$62,"CV")),IFERROR(INDEX(ASCOPE_PMESII!$I$3:$I$62,_xlfn.AGGREGATE(15,6,(ROW(ASCOPE_PMESII!$H$3:$H$62)-ROW(ASCOPE_PMESII!$H$3)+1)/(ASCOPE_PMESII!$H$3:$H$62="CV"),1-(COUNTIF(ASCOPE_PMESII!$B$3:$B$62,"CV")+COUNTIF(ASCOPE_PMESII!$D$3:$D$62,"CV")+COUNTIF(ASCOPE_PMESII!$F$3:$F$62,"CV")))),""),IF(1<=(COUNTIF(ASCOPE_PMESII!$B$3:$B$62,"CV")+COUNTIF(ASCOPE_PMESII!$D$3:$D$62,"CV")+COUNTIF(ASCOPE_PMESII!$F$3:$F$62,"CV")+COUNTIF(ASCOPE_PMESII!$H$3:$H$62,"CV")+COUNTIF(ASCOPE_PMESII!$J$3:$J$62,"CV")),IFERROR(INDEX(ASCOPE_PMESII!$K$3:$K$62,_xlfn.AGGREGATE(15,6,(ROW(ASCOPE_PMESII!$J$3:$J$62)-ROW(ASCOPE_PMESII!$J$3)+1)/(ASCOPE_PMESII!$J$3:$J$62="CV"),1-(COUNTIF(ASCOPE_PMESII!$B$3:$B$62,"CV")+COUNTIF(ASCOPE_PMESII!$D$3:$D$62,"CV")+COUNTIF(ASCOPE_PMESII!$F$3:$F$62,"CV")+COUNTIF(ASCOPE_PMESII!$H$3:$H$62,"CV")))),""),IFERROR(INDEX(ASCOPE_PMESII!$M$3:$M$62,_xlfn.AGGREGATE(15,6,(ROW(ASCOPE_PMESII!$L$3:$L$62)-ROW(ASCOPE_PMESII!$L$3)+1)/(ASCOPE_PMESII!$L$3:$L$62="CV"),1-(COUNTIF(ASCOPE_PMESII!$B$3:$B$62,"CV")+COUNTIF(ASCOPE_PMESII!$D$3:$D$62,"CV")+COUNTIF(ASCOPE_PMESII!$F$3:$F$62,"CV")+COUNTIF(ASCOPE_PMESII!$H$3:$H$62,"CV")+COUNTIF(ASCOPE_PMESII!$J$3:$J$62,"CV")))),"")))))),"")} -> Jakarta authority has collapsed across N Sumatra | E4: {=IFERROR(IF(1<=COUNTIF(ASCOPE_PMESII!$B$3:$B$62,"COR"),IFERROR(INDEX(ASCOPE_PMESII!$C$3:$C$62,_xlfn.AGGREGATE(15,6,(ROW(ASCOPE_PMESII!$B$3:$B$62)-ROW(ASCOPE_PMESII!$B$3)+1)/(ASCOPE_PMESII!$B$3:$B$62="COR"),1)),""),IF(1<=(COUNTIF(ASCOPE_PMESII!$B$3:$B$62,"COR")+COUNTIF(ASCOPE_PMESII!$D$3:$D$62,"COR")),IFERROR(INDEX(ASCOPE_PMESII!$E$3:$E$62,_xlfn.AGGREGATE(15,6,(ROW(ASCOPE_PMESII!$D$3:$D$62)-ROW(ASCOPE_PMESII!$D$3)+1)/(ASCOPE_PMESII!$D$3:$D$62="COR"),1-(COUNTIF(ASCOPE_PMESII!$B$3:$B$62,"COR")))),""),IF(1<=(COUNTIF(ASCOPE_PMESII!$B$3:$B$62,"COR")+COUNTIF(ASCOPE_PMESII!$D$3:$D$62,"COR")+COUNTIF(ASCOPE_PMESII!$F$3:$F$62,"COR")),IFERROR(INDEX(ASCOPE_PMESII!$G$3:$G$62,_xlfn.AGGREGATE(15,6,(ROW(ASCOPE_PMESII!$F$3:$F$62)-ROW(ASCOPE_PMESII!$F$3)+1)/(ASCOPE_PMESII!$F$3:$F$62="COR"),1-(COUNTIF(ASCOPE_PMESII!$B$3:$B$62,"COR")+COUNTIF(ASCOPE_PMESII!$D$3:$D$62,"COR")))),""),IF(1<=(COUNTIF(ASCOPE_PMESII!$B$3:$B$62,"COR")+COUNTIF(ASCOPE_PMESII!$D$3:$D$62,"COR")+COUNTIF(ASCOPE_PMESII!$F$3:$F$62,"COR")+COUNTIF(ASCOPE_PMESII!$H$3:$H$62,"COR")),IFERROR(INDEX(ASCOPE_PMESII!$I$3:$I$62,_xlfn.AGGREGATE(15,6,(ROW(ASCOPE_PMESII!$H$3:$H$62)-ROW(ASCOPE_PMESII!$H$3)+1)/(ASCOPE_PMESII!$H$3:$H$62="COR"),1-(COUNTIF(ASCOPE_PMESII!$B$3:$B$62,"COR")+COUNTIF(ASCOPE_PMESII!$D$3:$D$62,"COR")+COUNTIF(ASCOPE_PMESII!$F$3:$F$62,"COR")))),""),IF(1<=(COUNTIF(ASCOPE_PMESII!$B$3:$B$62,"COR")+COUNTIF(ASCOPE_PMESII!$D$3:$D$62,"COR")+COUNTIF(ASCOPE_PMESII!$F$3:$F$62,"COR")+COUNTIF(ASCOPE_PMESII!$H$3:$H$62,"COR")+COUNTIF(ASCOPE_PMESII!$J$3:$J$62,"COR")),IFERROR(INDEX(ASCOPE_PMESII!$K$3:$K$62,_xlfn.AGGREGATE(15,6,(ROW(ASCOPE_PMESII!$J$3:$J$62)-ROW(ASCOPE_PMESII!$J$3)+1)/(ASCOPE_PMESII!$J$3:$J$62="COR"),1-(COUNTIF(ASCOPE_PMESII!$B$3:$B$62,"COR")+COUNTIF(ASCOPE_PMESII!$D$3:$D$62,"COR")+COUNTIF(ASCOPE_PMESII!$F$3:$F$62,"COR")+COUNTIF(ASCOPE_PMESII!$H$3:$H$62,"COR")))),""),IFERROR(INDEX(ASCOPE_PMESII!$M$3:$M$62,_xlfn.AGGREGATE(15,6,(ROW(ASCOPE_PMESII!$L$3:$L$62)-ROW(ASCOPE_PMESII!$L$3)+1)/(ASCOPE_PMESII!$L$3:$L$62="COR"),1-(COUNTIF(ASCOPE_PMESII!$B$3:$B$62,"COR")+COUNTIF(ASCOPE_PMESII!$D$3:$D$62,"COR")+COUNTIF(ASCOPE_PMESII!$F$3:$F$62,"COR")+COUNTIF(ASCOPE_PMESII!$H$3:$H$62,"COR")+COUNTIF(ASCOPE_PMESII!$J$3:$J$62,"COR")))),"")))))),"")} -> Support GoIND sovereignty without Java-centric framing | F4: {=IFERROR(IF(1<=COUNTIF(ASCOPE_PMESII!$B$3:$B$62,"REQT"),IFERROR(INDEX(ASCOPE_PMESII!$C$3:$C$62,_xlfn.AGGREGATE(15,6,(ROW(ASCOPE_PMESII!$B$3:$B$62)-ROW(ASCOPE_PMESII!$B$3)+1)/(ASCOPE_PMESII!$B$3:$B$62="REQT"),1)),""),IF(1<=(COUNTIF(ASCOPE_PMESII!$B$3:$B$62,"REQT")+COUNTIF(ASCOPE_PMESII!$D$3:$D$62,"REQT")),IFERROR(INDEX(ASCOPE_PMESII!$E$3:$E$62,_xlfn.AGGREGATE(15,6,(ROW(ASCOPE_PMESII!$D$3:$D$62)-ROW(ASCOPE_PMESII!$D$3)+1)/(ASCOPE_PMESII!$D$3:$D$62="REQT"),1-(COUNTIF(ASCOPE_PMESII!$B$3:$B$62,"REQT")))),""),IF(1<=(COUNTIF(ASCOPE_PMESII!$B$3:$B$62,"REQT")+COUNTIF(ASCOPE_PMESII!$D$3:$D$62,"REQT")+COUNTIF(ASCOPE_PMESII!$F$3:$F$62,"REQT")),IFERROR(INDEX(ASCOPE_PMESII!$G$3:$G$62,_xlfn.AGGREGATE(15,6,(ROW(ASCOPE_PMESII!$F$3:$F$62)-ROW(ASCOPE_PMESII!$F$3)+1)/(ASCOPE_PMESII!$F$3:$F$62="REQT"),1-(COUNTIF(ASCOPE_PMESII!$B$3:$B$62,"REQT")+COUNTIF(ASCOPE_PMESII!$D$3:$D$62,"REQT")))),""),IF(1<=(COUNTIF(ASCOPE_PMESII!$B$3:$B$62,"REQT")+COUNTIF(ASCOPE_PMESII!$D$3:$D$62,"REQT")+COUNTIF(ASCOPE_PMESII!$F$3:$F$62,"REQT")+COUNTIF(ASCOPE_PMESII!$H$3:$H$62,"REQT")),IFERROR(INDEX(ASCOPE_PMESII!$I$3:$I$62,_xlfn.AGGREGATE(15,6,(ROW(ASCOPE_PMESII!$H$3:$H$62)-ROW(ASCOPE_PMESII!$H$3)+1)/(ASCOPE_PMESII!$H$3:$H$62="REQT"),1-(COUNTIF(ASCOPE_PMESII!$B$3:$B$62,"REQT")+COUNTIF(ASCOPE_PMESII!$D$3:$D$62,"REQT")+COUNTIF(ASCOPE_PMESII!$F$3:$F$62,"REQT")))),""),IF(1<=(COUNTIF(ASCOPE_PMESII!$B$3:$B$62,"REQT")+COUNTIF(ASCOPE_PMESII!$D$3:$D$62,"REQT")+COUNTIF(ASCOPE_PMESII!$F$3:$F$62,"REQT")+COUNTIF(ASCOPE_PMESII!$H$3:$H$62,"REQT")+COUNTIF(ASCOPE_PMESII!$J$3:$J$62,"REQT")),IFERROR(INDEX(ASCOPE_PMESII!$K$3:$K$62,_xlfn.AGGREGATE(15,6,(ROW(ASCOPE_PMESII!$J$3:$J$62)-ROW(ASCOPE_PMESII!$J$3)+1)/(ASCOPE_PMESII!$J$3:$J$62="REQT"),1-(COUNTIF(ASCOPE_PMESII!$B$3:$B$62,"REQT")+COUNTIF(ASCOPE_PMESII!$D$3:$D$62,"REQT")+COUNTIF(ASCOPE_PMESII!$F$3:$F$62,"REQT")+COUNTIF(ASCOPE_PMESII!$H$3:$H$62,"REQT")))),""),IFERROR(INDEX(ASCOPE_PMESII!$M$3:$M$62,_xlfn.AGGREGATE(15,6,(ROW(ASCOPE_PMESII!$L$3:$L$62)-ROW(ASCOPE_PMESII!$L$3)+1)/(ASCOPE_PMESII!$L$3:$L$62="REQT"),1-(COUNTIF(ASCOPE_PMESII!$B$3:$B$62,"REQT")+COUNTIF(ASCOPE_PMESII!$D$3:$D$62,"REQT")+COUNTIF(ASCOPE_PMESII!$F$3:$F$62,"REQT")+COUNTIF(ASCOPE_PMESII!$H$3:$H$62,"REQT")+COUNTIF(ASCOPE_PMESII!$J$3:$J$62,"REQT")))),"")))))),"")} -> Engineers and RSOI forces required early | G4: {=IFERROR(IF(1<=COUNTIF(ASCOPE_PMESII!$B$3:$B$62,"REST"),IFERROR(INDEX(ASCOPE_PMESII!$C$3:$C$62,_xlfn.AGGREGATE(15,6,(ROW(ASCOPE_PMESII!$B$3:$B$62)-ROW(ASCOPE_PMESII!$B$3)+1)/(ASCOPE_PMESII!$B$3:$B$62="REST"),1)),""),IF(1<=(COUNTIF(ASCOPE_PMESII!$B$3:$B$62,"REST")+COUNTIF(ASCOPE_PMESII!$D$3:$D$62,"REST")),IFERROR(INDEX(ASCOPE_PMESII!$E$3:$E$62,_xlfn.AGGREGATE(15,6,(ROW(ASCOPE_PMESII!$D$3:$D$62)-ROW(ASCOPE_PMESII!$D$3)+1)/(ASCOPE_PMESII!$D$3:$D$62="REST"),1-(COUNTIF(ASCOPE_PMESII!$B$3:$B$62,"REST")))),""),IF(1<=(COUNTIF(ASCOPE_PMESII!$B$3:$B$62,"REST")+COUNTIF(ASCOPE_PMESII!$D$3:$D$62,"REST")+COUNTIF(ASCOPE_PMESII!$F$3:$F$62,"REST")),IFERROR(INDEX(ASCOPE_PMESII!$G$3:$G$62,_xlfn.AGGREGATE(15,6,(ROW(ASCOPE_PMESII!$F$3:$F$62)-ROW(ASCOPE_PMESII!$F$3)+1)/(ASCOPE_PMESII!$F$3:$F$62="REST"),1-(COUNTIF(ASCOPE_PMESII!$B$3:$B$62,"REST")+COUNTIF(ASCOPE_PMESII!$D$3:$D$62,"REST")))),""),IF(1<=(COUNTIF(ASCOPE_PMESII!$B$3:$B$62,"REST")+COUNTIF(ASCOPE_PMESII!$D$3:$D$62,"REST")+COUNTIF(ASCOPE_PMESII!$F$3:$F$62,"REST")+COUNTIF(ASCOPE_PMESII!$H$3:$H$62,"REST")),IFERROR(INDEX(ASCOPE_PMESII!$I$3:$I$62,_xlfn.AGGREGATE(15,6,(ROW(ASCOPE_PMESII!$H$3:$H$62)-ROW(ASCOPE_PMESII!$H$3)+1)/(ASCOPE_PMESII!$H$3:$H$62="REST"),1-(COUNTIF(ASCOPE_PMESII!$B$3:$B$62,"REST")+COUNTIF(ASCOPE_PMESII!$D$3:$D$62,"REST")+COUNTIF(ASCOPE_PMESII!$F$3:$F$62,"REST")))),""),IF(1<=(COUNTIF(ASCOPE_PMESII!$B$3:$B$62,"REST")+COUNTIF(ASCOPE_PMESII!$D$3:$D$62,"REST")+COUNTIF(ASCOPE_PMESII!$F$3:$F$62,"REST")+COUNTIF(ASCOPE_PMESII!$H$3:$H$62,"REST")+COUNTIF(ASCOPE_PMESII!$J$3:$J$62,"REST")),IFERROR(INDEX(ASCOPE_PMESII!$K$3:$K$62,_xlfn.AGGREGATE(15,6,(ROW(ASCOPE_PMESII!$J$3:$J$62)-ROW(ASCOPE_PMESII!$J$3)+1)/(ASCOPE_PMESII!$J$3:$J$62="REST"),1-(COUNTIF(ASCOPE_PMESII!$B$3:$B$62,"REST")+COUNTIF(ASCOPE_PMESII!$D$3:$D$62,"REST")+COUNTIF(ASCOPE_PMESII!$F$3:$F$62,"REST")+COUNTIF(ASCOPE_PMESII!$H$3:$H$62,"REST")))),""),IFERROR(INDEX(ASCOPE_PMESII!$M$3:$M$62,_xlfn.AGGREGATE(15,6,(ROW(ASCOPE_PMESII!$L$3:$L$62)-ROW(ASCOPE_PMESII!$L$3)+1)/(ASCOPE_PMESII!$L$3:$L$62="REST"),1-(COUNTIF(ASCOPE_PMESII!$B$3:$B$62,"REST")+COUNTIF(ASCOPE_PMESII!$D$3:$D$62,"REST")+COUNTIF(ASCOPE_PMESII!$F$3:$F$62,"REST")+COUNTIF(ASCOPE_PMESII!$H$3:$H$62,"REST")+COUNTIF(ASCOPE_PMESII!$J$3:$J$62,"REST")))),"")))))),"")} | H4: {=IFERROR(IF(1<=COUNTIF(ASCOPE_PMESII!$B$3:$B$62,"KCD-MUST"),IFERROR(INDEX(ASCOPE_PMESII!$C$3:$C$62,_xlfn.AGGREGATE(15,6,(ROW(ASCOPE_PMESII!$B$3:$B$62)-ROW(ASCOPE_PMESII!$B$3)+1)/(ASCOPE_PMESII!$B$3:$B$62="KCD-MUST"),1)),""),IF(1<=(COUNTIF(ASCOPE_PMESII!$B$3:$B$62,"KCD-MUST")+COUNTIF(ASCOPE_PMESII!$D$3:$D$62,"KCD-MUST")),IFERROR(INDEX(ASCOPE_PMESII!$E$3:$E$62,_xlfn.AGGREGATE(15,6,(ROW(ASCOPE_PMESII!$D$3:$D$62)-ROW(ASCOPE_PMESII!$D$3)+1)/(ASCOPE_PMESII!$D$3:$D$62="KCD-MUST"),1-(COUNTIF(ASCOPE_PMESII!$B$3:$B$62,"KCD-MUST")))),""),IF(1<=(COUNTIF(ASCOPE_PMESII!$B$3:$B$62,"KCD-MUST")+COUNTIF(ASCOPE_PMESII!$D$3:$D$62,"KCD-MUST")+COUNTIF(ASCOPE_PMESII!$F$3:$F$62,"KCD-MUST")),IFERROR(INDEX(ASCOPE_PMESII!$G$3:$G$62,_xlfn.AGGREGATE(15,6,(ROW(ASCOPE_PMESII!$F$3:$F$62)-ROW(ASCOPE_PMESII!$F$3)+1)/(ASCOPE_PMESII!$F$3:$F$62="KCD-MUST"),1-(COUNTIF(ASCOPE_PMESII!$B$3:$B$62,"KCD-MUST")+COUNTIF(ASCOPE_PMESII!$D$3:$D$62,"KCD-MUST")))),""),IF(1<=(COUNTIF(ASCOPE_PMESII!$B$3:$B$62,"KCD-MUST")+COUNTIF(ASCOPE_PMESII!$D$3:$D$62,"KCD-MUST")+COUNTIF(ASCOPE_PMESII!$F$3:$F$62,"KCD-MUST")+COUNTIF(ASCOPE_PMESII!$H$3:$H$62,"KCD-MUST")),IFERROR(INDEX(ASCOPE_PMESII!$I$3:$I$62,_xlfn.AGGREGATE(15,6,(ROW(ASCOPE_PMESII!$H$3:$H$62)-ROW(ASCOPE_PMESII!$H$3)+1)/(ASCOPE_PMESII!$H$3:$H$62="KCD-MUST"),1-(COUNTIF(ASCOPE_PMESII!$B$3:$B$62,"KCD-MUST")+COUNTIF(ASCOPE_PMESII!$D$3:$D$62,"KCD-MUST")+COUNTIF(ASCOPE_PMESII!$F$3:$F$62,"KCD-MUST")))),""),IF(1<=(COUNTIF(ASCOPE_PMESII!$B$3:$B$62,"KCD-MUST")+COUNTIF(ASCOPE_PMESII!$D$3:$D$62,"KCD-MUST")+COUNTIF(ASCOPE_PMESII!$F$3:$F$62,"KCD-MUST")+COUNTIF(ASCOPE_PMESII!$H$3:$H$62,"KCD-MUST")+COUNTIF(ASCOPE_PMESII!$J$3:$J$62,"KCD-MUST")),IFERROR(INDEX(ASCOPE_PMESII!$K$3:$K$62,_xlfn.AGGREGATE(15,6,(ROW(ASCOPE_PMESII!$J$3:$J$62)-ROW(ASCOPE_PMESII!$J$3)+1)/(ASCOPE_PMESII!$J$3:$J$62="KCD-MUST"),1-(COUNTIF(ASCOPE_PMESII!$B$3:$B$62,"KCD-MUST")+COUNTIF(ASCOPE_PMESII!$D$3:$D$62,"KCD-MUST")+COUNTIF(ASCOPE_PMESII!$F$3:$F$62,"KCD-MUST")+COUNTIF(ASCOPE_PMESII!$H$3:$H$62,"KCD-MUST")))),""),IFERROR(INDEX(ASCOPE_PMESII!$M$3:$M$62,_xlfn.AGGREGATE(15,6,(ROW(ASCOPE_PMESII!$L$3:$L$62)-ROW(ASCOPE_PMESII!$L$3)+1)/(ASCOPE_PMESII!$L$3:$L$62="KCD-MUST"),1-(COUNTIF(ASCOPE_PMESII!$B$3:$B$62,"KCD-MUST")+COUNTIF(ASCOPE_PMESII!$D$3:$D$62,"KCD-MUST")+COUNTIF(ASCOPE_PMESII!$F$3:$F$62,"KCD-MUST")+COUNTIF(ASCOPE_PMESII!$H$3:$H$62,"KCD-MUST")+COUNTIF(ASCOPE_PMESII!$J$3:$J$62,"KCD-MUST")))),"")))))),"")} -> NATO must restore territorial integrity, not occupy Sumatra | I4: {=IFERROR(IF(1<=COUNTIF(ASCOPE_PMESII!$B$3:$B$62,"KCD-SHOULD"),IFERROR(INDEX(ASCOPE_PMESII!$C$3:$C$62,_xlfn.AGGREGATE(15,6,(ROW(ASCOPE_PMESII!$B$3:$B$62)-ROW(ASCOPE_PMESII!$B$3)+1)/(ASCOPE_PMESII!$B$3:$B$62="KCD-SHOULD"),1)),""),IF(1<=(COUNTIF(ASCOPE_PMESII!$B$3:$B$62,"KCD-SHOULD")+COUNTIF(ASCOPE_PMESII!$D$3:$D$62,"KCD-SHOULD")),IFERROR(INDEX(ASCOPE_PMESII!$E$3:$E$62,_xlfn.AGGREGATE(15,6,(ROW(ASCOPE_PMESII!$D$3:$D$62)-ROW(ASCOPE_PMESII!$D$3)+1)/(ASCOPE_PMESII!$D$3:$D$62="KCD-SHOULD"),1-(COUNTIF(ASCOPE_PMESII!$B$3:$B$62,"KCD-SHOULD")))),""),IF(1<=(COUNTIF(ASCOPE_PMESII!$B$3:$B$62,"KCD-SHOULD")+COUNTIF(ASCOPE_PMESII!$D$3:$D$62,"KCD-SHOULD")+COUNTIF(ASCOPE_PMESII!$F$3:$F$62,"KCD-SHOULD")),IFERROR(INDEX(ASCOPE_PMESII!$G$3:$G$62,_xlfn.AGGREGATE(15,6,(ROW(ASCOPE_PMESII!$F$3:$F$62)-ROW(ASCOPE_PMESII!$F$3)+1)/(ASCOPE_PMESII!$F$3:$F$62="KCD-SHOULD"),1-(COUNTIF(ASCOPE_PMESII!$B$3:$B$62,"KCD-SHOULD")+COUNTIF(ASCOPE_PMESII!$D$3:$D$62,"KCD-SHOULD")))),""),IF(1<=(COUNTIF(ASCOPE_PMESII!$B$3:$B$62,"KCD-SHOULD")+COUNTIF(ASCOPE_PMESII!$D$3:$D$62,"KCD-SHOULD")+COUNTIF(ASCOPE_PMESII!$F$3:$F$62,"KCD-SHOULD")+COUNTIF(ASCOPE_PMESII!$H$3:$H$62,"KCD-SHOULD")),IFERROR(INDEX(ASCOPE_PMESII!$I$3:$I$62,_xlfn.AGGREGATE(15,6,(ROW(ASCOPE_PMESII!$H$3:$H$62)-ROW(ASCOPE_PMESII!$H$3)+1)/(ASCOPE_PMESII!$H$3:$H$62="KCD-SHOULD"),1-(COUNTIF(ASCOPE_PMESII!$B$3:$B$62,"KCD-SHOULD")+COUNTIF(ASCOPE_PMESII!$D$3:$D$62,"KCD-SHOULD")+COUNTIF(ASCOPE_PMESII!$F$3:$F$62,"KCD-SHOULD")))),""),IF(1<=(COUNTIF(ASCOPE_PMESII!$B$3:$B$62,"KCD-SHOULD")+COUNTIF(ASCOPE_PMESII!$D$3:$D$62,"KCD-SHOULD")+COUNTIF(ASCOPE_PMESII!$F$3:$F$62,"KCD-SHOULD")+COUNTIF(ASCOPE_PMESII!$H$3:$H$62,"KCD-SHOULD")+COUNTIF(ASCOPE_PMESII!$J$3:$J$62,"KCD-SHOULD")),IFERROR(INDEX(ASCOPE_PMESII!$K$3:$K$62,_xlfn.AGGREGATE(15,6,(ROW(ASCOPE_PMESII!$J$3:$J$62)-ROW(ASCOPE_PMESII!$J$3)+1)/(ASCOPE_PMESII!$J$3:$J$62="KCD-SHOULD"),1-(COUNTIF(ASCOPE_PMESII!$B$3:$B$62,"KCD-SHOULD")+COUNTIF(ASCOPE_PMESII!$D$3:$D$62,"KCD-SHOULD")+COUNTIF(ASCOPE_PMESII!$F$3:$F$62,"KCD-SHOULD")+COUNTIF(ASCOPE_PMESII!$H$3:$H$62,"KCD-SHOULD")))),""),IFERROR(INDEX(ASCOPE_PMESII!$M$3:$M$62,_xlfn.AGGREGATE(15,6,(ROW(ASCOPE_PMESII!$L$3:$L$62)-ROW(ASCOPE_PMESII!$L$3)+1)/(ASCOPE_PMESII!$L$3:$L$62="KCD-SHOULD"),1-(COUNTIF(ASCOPE_PMESII!$B$3:$B$62,"KCD-SHOULD")+COUNTIF(ASCOPE_PMESII!$D$3:$D$62,"KCD-SHOULD")+COUNTIF(ASCOPE_PMESII!$F$3:$F$62,"KCD-SHOULD")+COUNTIF(ASCOPE_PMESII!$H$3:$H$62,"KCD-SHOULD")+COUNTIF(ASCOPE_PMESII!$J$3:$J$62,"KCD-SHOULD")))),"")))))),"")} -> Support visible GoIND lead at secured nodes | J4: {=IFERROR(IF(1<=COUNTIF(ASCOPE_PMESII!$B$3:$B$62,"KCD-SHOULD NOT"),IFERROR(INDEX(ASCOPE_PMESII!$C$3:$C$62,_xlfn.AGGREGATE(15,6,(ROW(ASCOPE_PMESII!$B$3:$B$62)-ROW(ASCOPE_PMESII!$B$3)+1)/(ASCOPE_PMESII!$B$3:$B$62="KCD-SHOULD NOT"),1)),""),IF(1<=(COUNTIF(ASCOPE_PMESII!$B$3:$B$62,"KCD-SHOULD NOT")+COUNTIF(ASCOPE_PMESII!$D$3:$D$62,"KCD-SHOULD NOT")),IFERROR(INDEX(ASCOPE_PMESII!$E$3:$E$62,_xlfn.AGGREGATE(15,6,(ROW(ASCOPE_PMESII!$D$3:$D$62)-ROW(ASCOPE_PMESII!$D$3)+1)/(ASCOPE_PMESII!$D$3:$D$62="KCD-SHOULD NOT"),1-(COUNTIF(ASCOPE_PMESII!$B$3:$B$62,"KCD-SHOULD NOT")))),""),IF(1<=(COUNTIF(ASCOPE_PMESII!$B$3:$B$62,"KCD-SHOULD NOT")+COUNTIF(ASCOPE_PMESII!$D$3:$D$62,"KCD-SHOULD NOT")+COUNTIF(ASCOPE_PMESII!$F$3:$F$62,"KCD-SHOULD NOT")),IFERROR(INDEX(ASCOPE_PMESII!$G$3:$G$62,_xlfn.AGGREGATE(15,6,(ROW(ASCOPE_PMESII!$F$3:$F$62)-ROW(ASCOPE_PMESII!$F$3)+1)/(ASCOPE_PMESII!$F$3:$F$62="KCD-SHOULD NOT"),1-(COUNTIF(ASCOPE_PMESII!$B$3:$B$62,"KCD-SHOULD NOT")+COUNTIF(ASCOPE_PMESII!$D$3:$D$62,"KCD-SHOULD NOT")))),""),IF(1<=(COUNTIF(ASCOPE_PMESII!$B$3:$B$62,"KCD-SHOULD NOT")+COUNTIF(ASCOPE_PMESII!$D$3:$D$62,"KCD-SHOULD NOT")+COUNTIF(ASCOPE_PMESII!$F$3:$F$62,"KCD-SHOULD NOT")+COUNTIF(ASCOPE_PMESII!$H$3:$H$62,"KCD-SHOULD NOT")),IFERROR(INDEX(ASCOPE_PMESII!$I$3:$I$62,_xlfn.AGGREGATE(15,6,(ROW(ASCOPE_PMESII!$H$3:$H$62)-ROW(ASCOPE_PMESII!$H$3)+1)/(ASCOPE_PMESII!$H$3:$H$62="KCD-SHOULD NOT"),1-(COUNTIF(ASCOPE_PMESII!$B$3:$B$62,"KCD-SHOULD NOT")+COUNTIF(ASCOPE_PMESII!$D$3:$D$62,"KCD-SHOULD NOT")+COUNTIF(ASCOPE_PMESII!$F$3:$F$62,"KCD-SHOULD NOT")))),""),IF(1<=(COUNTIF(ASCOPE_PMESII!$B$3:$B$62,"KCD-SHOULD NOT")+COUNTIF(ASCOPE_PMESII!$D$3:$D$62,"KCD-SHOULD NOT")+COUNTIF(ASCOPE_PMESII!$F$3:$F$62,"KCD-SHOULD NOT")+COUNTIF(ASCOPE_PMESII!$H$3:$H$62,"KCD-SHOULD NOT")+COUNTIF(ASCOPE_PMESII!$J$3:$J$62,"KCD-SHOULD NOT")),IFERROR(INDEX(ASCOPE_PMESII!$K$3:$K$62,_xlfn.AGGREGATE(15,6,(ROW(ASCOPE_PMESII!$J$3:$J$62)-ROW(ASCOPE_PMESII!$J$3)+1)/(ASCOPE_PMESII!$J$3:$J$62="KCD-SHOULD NOT"),1-(COUNTIF(ASCOPE_PMESII!$B$3:$B$62,"KCD-SHOULD NOT")+COUNTIF(ASCOPE_PMESII!$D$3:$D$62,"KCD-SHOULD NOT")+COUNTIF(ASCOPE_PMESII!$F$3:$F$62,"KCD-SHOULD NOT")+COUNTIF(ASCOPE_PMESII!$H$3:$H$62,"KCD-SHOULD NOT")))),""),IFERROR(INDEX(ASCOPE_PMESII!$M$3:$M$62,_xlfn.AGGREGATE(15,6,(ROW(ASCOPE_PMESII!$L$3:$L$62)-ROW(ASCOPE_PMESII!$L$3)+1)/(ASCOPE_PMESII!$L$3:$L$62="KCD-SHOULD NOT"),1-(COUNTIF(ASCOPE_PMESII!$B$3:$B$62,"KCD-SHOULD NOT")+COUNTIF(ASCOPE_PMESII!$D$3:$D$62,"KCD-SHOULD NOT")+COUNTIF(ASCOPE_PMESII!$F$3:$F$62,"KCD-SHOULD NOT")+COUNTIF(ASCOPE_PMESII!$H$3:$H$62,"KCD-SHOULD NOT")+COUNTIF(ASCOPE_PMESII!$J$3:$J$62,"KCD-SHOULD NOT")))),"")))))),"")} | K4: {=IFERROR(IF(1<=COUNTIF(ASCOPE_PMESII!$B$3:$B$62,"KCD-CANNOT"),IFERROR(INDEX(ASCOPE_PMESII!$C$3:$C$62,_xlfn.AGGREGATE(15,6,(ROW(ASCOPE_PMESII!$B$3:$B$62)-ROW(ASCOPE_PMESII!$B$3)+1)/(ASCOPE_PMESII!$B$3:$B$62="KCD-CANNOT"),1)),""),IF(1<=(COUNTIF(ASCOPE_PMESII!$B$3:$B$62,"KCD-CANNOT")+COUNTIF(ASCOPE_PMESII!$D$3:$D$62,"KCD-CANNOT")),IFERROR(INDEX(ASCOPE_PMESII!$E$3:$E$62,_xlfn.AGGREGATE(15,6,(ROW(ASCOPE_PMESII!$D$3:$D$62)-ROW(ASCOPE_PMESII!$D$3)+1)/(ASCOPE_PMESII!$D$3:$D$62="KCD-CANNOT"),1-(COUNTIF(ASCOPE_PMESII!$B$3:$B$62,"KCD-CANNOT")))),""),IF(1<=(COUNTIF(ASCOPE_PMESII!$B$3:$B$62,"KCD-CANNOT")+COUNTIF(ASCOPE_PMESII!$D$3:$D$62,"KCD-CANNOT")+COUNTIF(ASCOPE_PMESII!$F$3:$F$62,"KCD-CANNOT")),IFERROR(INDEX(ASCOPE_PMESII!$G$3:$G$62,_xlfn.AGGREGATE(15,6,(ROW(ASCOPE_PMESII!$F$3:$F$62)-ROW(ASCOPE_PMESII!$F$3)+1)/(ASCOPE_PMESII!$F$3:$F$62="KCD-CANNOT"),1-(COUNTIF(ASCOPE_PMESII!$B$3:$B$62,"KCD-CANNOT")+COUNTIF(ASCOPE_PMESII!$D$3:$D$62,"KCD-CANNOT")))),""),IF(1<=(COUNTIF(ASCOPE_PMESII!$B$3:$B$62,"KCD-CANNOT")+COUNTIF(ASCOPE_PMESII!$D$3:$D$62,"KCD-CANNOT")+COUNTIF(ASCOPE_PMESII!$F$3:$F$62,"KCD-CANNOT")+COUNTIF(ASCOPE_PMESII!$H$3:$H$62,"KCD-CANNOT")),IFERROR(INDEX(ASCOPE_PMESII!$I$3:$I$62,_xlfn.AGGREGATE(15,6,(ROW(ASCOPE_PMESII!$H$3:$H$62)-ROW(ASCOPE_PMESII!$H$3)+1)/(ASCOPE_PMESII!$H$3:$H$62="KCD-CANNOT"),1-(COUNTIF(ASCOPE_PMESII!$B$3:$B$62,"KCD-CANNOT")+COUNTIF(ASCOPE_PMESII!$D$3:$D$62,"KCD-CANNOT")+COUNTIF(ASCOPE_PMESII!$F$3:$F$62,"KCD-CANNOT")))),""),IF(1<=(COUNTIF(ASCOPE_PMESII!$B$3:$B$62,"KCD-CANNOT")+COUNTIF(ASCOPE_PMESII!$D$3:$D$62,"KCD-CANNOT")+COUNTIF(ASCOPE_PMESII!$F$3:$F$62,"KCD-CANNOT")+COUNTIF(ASCOPE_PMESII!$H$3:$H$62,"KCD-CANNOT")+COUNTIF(ASCOPE_PMESII!$J$3:$J$62,"KCD-CANNOT")),IFERROR(INDEX(ASCOPE_PMESII!$K$3:$K$62,_xlfn.AGGREGATE(15,6,(ROW(ASCOPE_PMESII!$J$3:$J$62)-ROW(ASCOPE_PMESII!$J$3)+1)/(ASCOPE_PMESII!$J$3:$J$62="KCD-CANNOT"),1-(COUNTIF(ASCOPE_PMESII!$B$3:$B$62,"KCD-CANNOT")+COUNTIF(ASCOPE_PMESII!$D$3:$D$62,"KCD-CANNOT")+COUNTIF(ASCOPE_PMESII!$F$3:$F$62,"KCD-CANNOT")+COUNTIF(ASCOPE_PMESII!$H$3:$H$62,"KCD-CANNOT")))),""),IFERROR(INDEX(ASCOPE_PMESII!$M$3:$M$62,_xlfn.AGGREGATE(15,6,(ROW(ASCOPE_PMESII!$L$3:$L$62)-ROW(ASCOPE_PMESII!$L$3)+1)/(ASCOPE_PMESII!$L$3:$L$62="KCD-CANNOT"),1-(COUNTIF(ASCOPE_PMESII!$B$3:$B$62,"KCD-CANNOT")+COUNTIF(ASCOPE_PMESII!$D$3:$D$62,"KCD-CANNOT")+COUNTIF(ASCOPE_PMESII!$F$3:$F$62,"KCD-CANNOT")+COUNTIF(ASCOPE_PMESII!$H$3:$H$62,"KCD-CANNOT")+COUNTIF(ASCOPE_PMESII!$J$3:$J$62,"KCD-CANNOT")))),"")))))),"")} -> Cannot treat Sumatra as uniform political terrain | L4: {=IFERROR(IF(1<=COUNTIF(ASCOPE_PMESII!$B$3:$B$62,"DECISION"),IFERROR(INDEX(ASCOPE_PMESII!$C$3:$C$62,_xlfn.AGGREGATE(15,6,(ROW(ASCOPE_PMESII!$B$3:$B$62)-ROW(ASCOPE_PMESII!$B$3)+1)/(ASCOPE_PMESII!$B$3:$B$62="DECISION"),1)),""),IF(1<=(COUNTIF(ASCOPE_PMESII!$B$3:$B$62,"DECISION")+COUNTIF(ASCOPE_PMESII!$D$3:$D$62,"DECISION")),IFERROR(INDEX(ASCOPE_PMESII!$E$3:$E$62,_xlfn.AGGREGATE(15,6,(ROW(ASCOPE_PMESII!$D$3:$D$62)-ROW(ASCOPE_PMESII!$D$3)+1)/(ASCOPE_PMESII!$D$3:$D$62="DECISION"),1-(COUNTIF(ASCOPE_PMESII!$B$3:$B$62,"DECISION")))),""),IF(1<=(COUNTIF(ASCOPE_PMESII!$B$3:$B$62,"DECISION")+COUNTIF(ASCOPE_PMESII!$D$3:$D$62,"DECISION")+COUNTIF(ASCOPE_PMESII!$F$3:$F$62,"DECISION")),IFERROR(INDEX(ASCOPE_PMESII!$G$3:$G$62,_xlfn.AGGREGATE(15,6,(ROW(ASCOPE_PMESII!$F$3:$F$62)-ROW(ASCOPE_PMESII!$F$3)+1)/(ASCOPE_PMESII!$F$3:$F$62="DECISION"),1-(COUNTIF(ASCOPE_PMESII!$B$3:$B$62,"DECISION")+COUNTIF(ASCOPE_PMESII!$D$3:$D$62,"DECISION")))),""),IF(1<=(COUNTIF(ASCOPE_PMESII!$B$3:$B$62,"DECISION")+COUNTIF(ASCOPE_PMESII!$D$3:$D$62,"DECISION")+COUNTIF(ASCOPE_PMESII!$F$3:$F$62,"DECISION")+COUNTIF(ASCOPE_PMESII!$H$3:$H$62,"DECISION")),IFERROR(INDEX(ASCOPE_PMESII!$I$3:$I$62,_xlfn.AGGREGATE(15,6,(ROW(ASCOPE_PMESII!$H$3:$H$62)-ROW(ASCOPE_PMESII!$H$3)+1)/(ASCOPE_PMESII!$H$3:$H$62="DECISION"),1-(COUNTIF(ASCOPE_PMESII!$B$3:$B$62,"DECISION")+COUNTIF(ASCOPE_PMESII!$D$3:$D$62,"DECISION")+COUNTIF(ASCOPE_PMESII!$F$3:$F$62,"DECISION")))),""),IF(1<=(COUNTIF(ASCOPE_PMESII!$B$3:$B$62,"DECISION")+COUNTIF(ASCOPE_PMESII!$D$3:$D$62,"DECISION")+COUNTIF(ASCOPE_PMESII!$F$3:$F$62,"DECISION")+COUNTIF(ASCOPE_PMESII!$H$3:$H$62,"DECISION")+COUNTIF(ASCOPE_PMESII!$J$3:$J$62,"DECISION")),IFERROR(INDEX(ASCOPE_PMESII!$K$3:$K$62,_xlfn.AGGREGATE(15,6,(ROW(ASCOPE_PMESII!$J$3:$J$62)-ROW(ASCOPE_PMESII!$J$3)+1)/(ASCOPE_PMESII!$J$3:$J$62="DECISION"),1-(COUNTIF(ASCOPE_PMESII!$B$3:$B$62,"DECISION")+COUNTIF(ASCOPE_PMESII!$D$3:$D$62,"DECISION")+COUNTIF(ASCOPE_PMESII!$F$3:$F$62,"DECISION")+COUNTIF(ASCOPE_PMESII!$H$3:$H$62,"DECISION")))),""),IFERROR(INDEX(ASCOPE_PMESII!$M$3:$M$62,_xlfn.AGGREGATE(15,6,(ROW(ASCOPE_PMESII!$L$3:$L$62)-ROW(ASCOPE_PMESII!$L$3)+1)/(ASCOPE_PMESII!$L$3:$L$62="DECISION"),1-(COUNTIF(ASCOPE_PMESII!$B$3:$B$62,"DECISION")+COUNTIF(ASCOPE_PMESII!$D$3:$D$62,"DECISION")+COUNTIF(ASCOPE_PMESII!$F$3:$F$62,"DECISION")+COUNTIF(ASCOPE_PMESII!$H$3:$H$62,"DECISION")+COUNTIF(ASCOPE_PMESII!$J$3:$J$62,"DECISION")))),"")))))),"")} -> COM needs access priority and HNS risk decision | M4: {=IFERROR(IF(1<=COUNTIF(ASCOPE_PMESII!$B$3:$B$62,"ASSUMPTION"),IFERROR(INDEX(ASCOPE_PMESII!$C$3:$C$62,_xlfn.AGGREGATE(15,6,(ROW(ASCOPE_PMESII!$B$3:$B$62)-ROW(ASCOPE_PMESII!$B$3)+1)/(ASCOPE_PMESII!$B$3:$B$62="ASSUMPTION"),1)),""),IF(1<=(COUNTIF(ASCOPE_PMESII!$B$3:$B$62,"ASSUMPTION")+COUNTIF(ASCOPE_PMESII!$D$3:$D$62,"ASSUMPTION")),IFERROR(INDEX(ASCOPE_PMESII!$E$3:$E$62,_xlfn.AGGREGATE(15,6,(ROW(ASCOPE_PMESII!$D$3:$D$62)-ROW(ASCOPE_PMESII!$D$3)+1)/(ASCOPE_PMESII!$D$3:$D$62="ASSUMPTION"),1-(COUNTIF(ASCOPE_PMESII!$B$3:$B$62,"ASSUMPTION")))),""),IF(1<=(COUNTIF(ASCOPE_PMESII!$B$3:$B$62,"ASSUMPTION")+COUNTIF(ASCOPE_PMESII!$D$3:$D$62,"ASSUMPTION")+COUNTIF(ASCOPE_PMESII!$F$3:$F$62,"ASSUMPTION")),IFERROR(INDEX(ASCOPE_PMESII!$G$3:$G$62,_xlfn.AGGREGATE(15,6,(ROW(ASCOPE_PMESII!$F$3:$F$62)-ROW(ASCOPE_PMESII!$F$3)+1)/(ASCOPE_PMESII!$F$3:$F$62="ASSUMPTION"),1-(COUNTIF(ASCOPE_PMESII!$B$3:$B$62,"ASSUMPTION")+COUNTIF(ASCOPE_PMESII!$D$3:$D$62,"ASSUMPTION")))),""),IF(1<=(COUNTIF(ASCOPE_PMESII!$B$3:$B$62,"ASSUMPTION")+COUNTIF(ASCOPE_PMESII!$D$3:$D$62,"ASSUMPTION")+COUNTIF(ASCOPE_PMESII!$F$3:$F$62,"ASSUMPTION")+COUNTIF(ASCOPE_PMESII!$H$3:$H$62,"ASSUMPTION")),IFERROR(INDEX(ASCOPE_PMESII!$I$3:$I$62,_xlfn.AGGREGATE(15,6,(ROW(ASCOPE_PMESII!$H$3:$H$62)-ROW(ASCOPE_PMESII!$H$3)+1)/(ASCOPE_PMESII!$H$3:$H$62="ASSUMPTION"),1-(COUNTIF(ASCOPE_PMESII!$B$3:$B$62,"ASSUMPTION")+COUNTIF(ASCOPE_PMESII!$D$3:$D$62,"ASSUMPTION")+COUNTIF(ASCOPE_PMESII!$F$3:$F$62,"ASSUMPTION")))),""),IF(1<=(COUNTIF(ASCOPE_PMESII!$B$3:$B$62,"ASSUMPTION")+COUNTIF(ASCOPE_PMESII!$D$3:$D$62,"ASSUMPTION")+COUNTIF(ASCOPE_PMESII!$F$3:$F$62,"ASSUMPTION")+COUNTIF(ASCOPE_PMESII!$H$3:$H$62,"ASSUMPTION")+COUNTIF(ASCOPE_PMESII!$J$3:$J$62,"ASSUMPTION")),IFERROR(INDEX(ASCOPE_PMESII!$K$3:$K$62,_xlfn.AGGREGATE(15,6,(ROW(ASCOPE_PMESII!$J$3:$J$62)-ROW(ASCOPE_PMESII!$J$3)+1)/(ASCOPE_PMESII!$J$3:$J$62="ASSUMPTION"),1-(COUNTIF(ASCOPE_PMESII!$B$3:$B$62,"ASSUMPTION")+COUNTIF(ASCOPE_PMESII!$D$3:$D$62,"ASSUMPTION")+COUNTIF(ASCOPE_PMESII!$F$3:$F$62,"ASSUMPTION")+COUNTIF(ASCOPE_PMESII!$H$3:$H$62,"ASSUMPTION")))),""),IFERROR(INDEX(ASCOPE_PMESII!$M$3:$M$62,_xlfn.AGGREGATE(15,6,(ROW(ASCOPE_PMESII!$L$3:$L$62)-ROW(ASCOPE_PMESII!$L$3)+1)/(ASCOPE_PMESII!$L$3:$L$62="ASSUMPTION"),1-(COUNTIF(ASCOPE_PMESII!$B$3:$B$62,"ASSUMPTION")+COUNTIF(ASCOPE_PMESII!$D$3:$D$62,"ASSUMPTION")+COUNTIF(ASCOPE_PMESII!$F$3:$F$62,"ASSUMPTION")+COUNTIF(ASCOPE_PMESII!$H$3:$H$62,"ASSUMPTION")+COUNTIF(ASCOPE_PMESII!$J$3:$J$62,"ASSUMPTION")))),"")))))),"")} | N4: {=IFERROR(IF(1<=COUNTIF(ASCOPE_PMESII!$B$3:$B$62,"CONSTRAINT"),IFERROR(INDEX(ASCOPE_PMESII!$C$3:$C$62,_xlfn.AGGREGATE(15,6,(ROW(ASCOPE_PMESII!$B$3:$B$62)-ROW(ASCOPE_PMESII!$B$3)+1)/(ASCOPE_PMESII!$B$3:$B$62="CONSTRAINT"),1)),""),IF(1<=(COUNTIF(ASCOPE_PMESII!$B$3:$B$62,"CONSTRAINT")+COUNTIF(ASCOPE_PMESII!$D$3:$D$62,"CONSTRAINT")),IFERROR(INDEX(ASCOPE_PMESII!$E$3:$E$62,_xlfn.AGGREGATE(15,6,(ROW(ASCOPE_PMESII!$D$3:$D$62)-ROW(ASCOPE_PMESII!$D$3)+1)/(ASCOPE_PMESII!$D$3:$D$62="CONSTRAINT"),1-(COUNTIF(ASCOPE_PMESII!$B$3:$B$62,"CONSTRAINT")))),""),IF(1<=(COUNTIF(ASCOPE_PMESII!$B$3:$B$62,"CONSTRAINT")+COUNTIF(ASCOPE_PMESII!$D$3:$D$62,"CONSTRAINT")+COUNTIF(ASCOPE_PMESII!$F$3:$F$62,"CONSTRAINT")),IFERROR(INDEX(ASCOPE_PMESII!$G$3:$G$62,_xlfn.AGGREGATE(15,6,(ROW(ASCOPE_PMESII!$F$3:$F$62)-ROW(ASCOPE_PMESII!$F$3)+1)/(ASCOPE_PMESII!$F$3:$F$62="CONSTRAINT"),1-(COUNTIF(ASCOPE_PMESII!$B$3:$B$62,"CONSTRAINT")+COUNTIF(ASCOPE_PMESII!$D$3:$D$62,"CONSTRAINT")))),""),IF(1<=(COUNTIF(ASCOPE_PMESII!$B$3:$B$62,"CONSTRAINT")+COUNTIF(ASCOPE_PMESII!$D$3:$D$62,"CONSTRAINT")+COUNTIF(ASCOPE_PMESII!$F$3:$F$62,"CONSTRAINT")+COUNTIF(ASCOPE_PMESII!$H$3:$H$62,"CONSTRAINT")),IFERROR(INDEX(ASCOPE_PMESII!$I$3:$I$62,_xlfn.AGGREGATE(15,6,(ROW(ASCOPE_PMESII!$H$3:$H$62)-ROW(ASCOPE_PMESII!$H$3)+1)/(ASCOPE_PMESII!$H$3:$H$62="CONSTRAINT"),1-(COUNTIF(ASCOPE_PMESII!$B$3:$B$62,"CONSTRAINT")+COUNTIF(ASCOPE_PMESII!$D$3:$D$62,"CONSTRAINT")+COUNTIF(ASCOPE_PMESII!$F$3:$F$62,"CONSTRAINT")))),""),IF(1<=(COUNTIF(ASCOPE_PMESII!$B$3:$B$62,"CONSTRAINT")+COUNTIF(ASCOPE_PMESII!$D$3:$D$62,"CONSTRAINT")+COUNTIF(ASCOPE_PMESII!$F$3:$F$62,"CONSTRAINT")+COUNTIF(ASCOPE_PMESII!$H$3:$H$62,"CONSTRAINT")+COUNTIF(ASCOPE_PMESII!$J$3:$J$62,"CONSTRAINT")),IFERROR(INDEX(ASCOPE_PMESII!$K$3:$K$62,_xlfn.AGGREGATE(15,6,(ROW(ASCOPE_PMESII!$J$3:$J$62)-ROW(ASCOPE_PMESII!$J$3)+1)/(ASCOPE_PMESII!$J$3:$J$62="CONSTRAINT"),1-(COUNTIF(ASCOPE_PMESII!$B$3:$B$62,"CONSTRAINT")+COUNTIF(ASCOPE_PMESII!$D$3:$D$62,"CONSTRAINT")+COUNTIF(ASCOPE_PMESII!$F$3:$F$62,"CONSTRAINT")+COUNTIF(ASCOPE_PMESII!$H$3:$H$62,"CONSTRAINT")))),""),IFERROR(INDEX(ASCOPE_PMESII!$M$3:$M$62,_xlfn.AGGREGATE(15,6,(ROW(ASCOPE_PMESII!$L$3:$L$62)-ROW(ASCOPE_PMESII!$L$3)+1)/(ASCOPE_PMESII!$L$3:$L$62="CONSTRAINT"),1-(COUNTIF(ASCOPE_PMESII!$B$3:$B$62,"CONSTRAINT")+COUNTIF(ASCOPE_PMESII!$D$3:$D$62,"CONSTRAINT")+COUNTIF(ASCOPE_PMESII!$F$3:$F$62,"CONSTRAINT")+COUNTIF(ASCOPE_PMESII!$H$3:$H$62,"CONSTRAINT")+COUNTIF(ASCOPE_PMESII!$J$3:$J$62,"CONSTRAINT")))),"")))))),"")} | O4: {=IFERROR(IF(1<=COUNTIF(ASCOPE_PMESII!$B$3:$B$62,"LIMITATION"),IFERROR(INDEX(ASCOPE_PMESII!$C$3:$C$62,_xlfn.AGGREGATE(15,6,(ROW(ASCOPE_PMESII!$B$3:$B$62)-ROW(ASCOPE_PMESII!$B$3)+1)/(ASCOPE_PMESII!$B$3:$B$62="LIMITATION"),1)),""),IF(1<=(COUNTIF(ASCOPE_PMESII!$B$3:$B$62,"LIMITATION")+COUNTIF(ASCOPE_PMESII!$D$3:$D$62,"LIMITATION")),IFERROR(INDEX(ASCOPE_PMESII!$E$3:$E$62,_xlfn.AGGREGATE(15,6,(ROW(ASCOPE_PMESII!$D$3:$D$62)-ROW(ASCOPE_PMESII!$D$3)+1)/(ASCOPE_PMESII!$D$3:$D$62="LIMITATION"),1-(COUNTIF(ASCOPE_PMESII!$B$3:$B$62,"LIMITATION")))),""),IF(1<=(COUNTIF(ASCOPE_PMESII!$B$3:$B$62,"LIMITATION")+COUNTIF(ASCOPE_PMESII!$D$3:$D$62,"LIMITATION")+COUNTIF(ASCOPE_PMESII!$F$3:$F$62,"LIMITATION")),IFERROR(INDEX(ASCOPE_PMESII!$G$3:$G$62,_xlfn.AGGREGATE(15,6,(ROW(ASCOPE_PMESII!$F$3:$F$62)-ROW(ASCOPE_PMESII!$F$3)+1)/(ASCOPE_PMESII!$F$3:$F$62="LIMITATION"),1-(COUNTIF(ASCOPE_PMESII!$B$3:$B$62,"LIMITATION")+COUNTIF(ASCOPE_PMESII!$D$3:$D$62,"LIMITATION")))),""),IF(1<=(COUNTIF(ASCOPE_PMESII!$B$3:$B$62,"LIMITATION")+COUNTIF(ASCOPE_PMESII!$D$3:$D$62,"LIMITATION")+COUNTIF(ASCOPE_PMESII!$F$3:$F$62,"LIMITATION")+COUNTIF(ASCOPE_PMESII!$H$3:$H$62,"LIMITATION")),IFERROR(INDEX(ASCOPE_PMESII!$I$3:$I$62,_xlfn.AGGREGATE(15,6,(ROW(ASCOPE_PMESII!$H$3:$H$62)-ROW(ASCOPE_PMESII!$H$3)+1)/(ASCOPE_PMESII!$H$3:$H$62="LIMITATION"),1-(COUNTIF(ASCOPE_PMESII!$B$3:$B$62,"LIMITATION")+COUNTIF(ASCOPE_PMESII!$D$3:$D$62,"LIMITATION")+COUNTIF(ASCOPE_PMESII!$F$3:$F$62,"LIMITATION")))),""),IF(1<=(COUNTIF(ASCOPE_PMESII!$B$3:$B$62,"LIMITATION")+COUNTIF(ASCOPE_PMESII!$D$3:$D$62,"LIMITATION")+COUNTIF(ASCOPE_PMESII!$F$3:$F$62,"LIMITATION")+COUNTIF(ASCOPE_PMESII!$H$3:$H$62,"LIMITATION")+COUNTIF(ASCOPE_PMESII!$J$3:$J$62,"LIMITATION")),IFERROR(INDEX(ASCOPE_PMESII!$K$3:$K$62,_xlfn.AGGREGATE(15,6,(ROW(ASCOPE_PMESII!$J$3:$J$62)-ROW(ASCOPE_PMESII!$J$3)+1)/(ASCOPE_PMESII!$J$3:$J$62="LIMITATION"),1-(COUNTIF(ASCOPE_PMESII!$B$3:$B$62,"LIMITATION")+COUNTIF(ASCOPE_PMESII!$D$3:$D$62,"LIMITATION")+COUNTIF(ASCOPE_PMESII!$F$3:$F$62,"LIMITATION")+COUNTIF(ASCOPE_PMESII!$H$3:$H$62,"LIMITATION")))),""),IFERROR(INDEX(ASCOPE_PMESII!$M$3:$M$62,_xlfn.AGGREGATE(15,6,(ROW(ASCOPE_PMESII!$L$3:$L$62)-ROW(ASCOPE_PMESII!$L$3)+1)/(ASCOPE_PMESII!$L$3:$L$62="LIMITATION"),1-(COUNTIF(ASCOPE_PMESII!$B$3:$B$62,"LIMITATION")+COUNTIF(ASCOPE_PMESII!$D$3:$D$62,"LIMITATION")+COUNTIF(ASCOPE_PMESII!$F$3:$F$62,"LIMITATION")+COUNTIF(ASCOPE_PMESII!$H$3:$H$62,"LIMITATION")+COUNTIF(ASCOPE_PMESII!$J$3:$J$62,"LIMITATION")))),"")))))),"")} | P4: {=IFERROR(IF(1<=COUNTIF(ASCOPE_PMESII!$B$3:$B$62,"CC"),IFERROR(INDEX(ASCOPE_PMESII!$C$3:$C$62,_xlfn.AGGREGATE(15,6,(ROW(ASCOPE_PMESII!$B$3:$B$62)-ROW(ASCOPE_PMESII!$B$3)+1)/(ASCOPE_PMESII!$B$3:$B$62="CC"),1)),""),IF(1<=(COUNTIF(ASCOPE_PMESII!$B$3:$B$62,"CC")+COUNTIF(ASCOPE_PMESII!$D$3:$D$62,"CC")),IFERROR(INDEX(ASCOPE_PMESII!$E$3:$E$62,_xlfn.AGGREGATE(15,6,(ROW(ASCOPE_PMESII!$D$3:$D$62)-ROW(ASCOPE_PMESII!$D$3)+1)/(ASCOPE_PMESII!$D$3:$D$62="CC"),1-(COUNTIF(ASCOPE_PMESII!$B$3:$B$62,"CC")))),""),IF(1<=(COUNTIF(ASCOPE_PMESII!$B$3:$B$62,"CC")+COUNTIF(ASCOPE_PMESII!$D$3:$D$62,"CC")+COUNTIF(ASCOPE_PMESII!$F$3:$F$62,"CC")),IFERROR(INDEX(ASCOPE_PMESII!$G$3:$G$62,_xlfn.AGGREGATE(15,6,(ROW(ASCOPE_PMESII!$F$3:$F$62)-ROW(ASCOPE_PMESII!$F$3)+1)/(ASCOPE_PMESII!$F$3:$F$62="CC"),1-(COUNTIF(ASCOPE_PMESII!$B$3:$B$62,"CC")+COUNTIF(ASCOPE_PMESII!$D$3:$D$62,"CC")))),""),IF(1<=(COUNTIF(ASCOPE_PMESII!$B$3:$B$62,"CC")+COUNTIF(ASCOPE_PMESII!$D$3:$D$62,"CC")+COUNTIF(ASCOPE_PMESII!$F$3:$F$62,"CC")+COUNTIF(ASCOPE_PMESII!$H$3:$H$62,"CC")),IFERROR(INDEX(ASCOPE_PMESII!$I$3:$I$62,_xlfn.AGGREGATE(15,6,(ROW(ASCOPE_PMESII!$H$3:$H$62)-ROW(ASCOPE_PMESII!$H$3)+1)/(ASCOPE_PMESII!$H$3:$H$62="CC"),1-(COUNTIF(ASCOPE_PMESII!$B$3:$B$62,"CC")+COUNTIF(ASCOPE_PMESII!$D$3:$D$62,"CC")+COUNTIF(ASCOPE_PMESII!$F$3:$F$62,"CC")))),""),IF(1<=(COUNTIF(ASCOPE_PMESII!$B$3:$B$62,"CC")+COUNTIF(ASCOPE_PMESII!$D$3:$D$62,"CC")+COUNTIF(ASCOPE_PMESII!$F$3:$F$62,"CC")+COUNTIF(ASCOPE_PMESII!$H$3:$H$62,"CC")+COUNTIF(ASCOPE_PMESII!$J$3:$J$62,"CC")),IFERROR(INDEX(ASCOPE_PMESII!$K$3:$K$62,_xlfn.AGGREGATE(15,6,(ROW(ASCOPE_PMESII!$J$3:$J$62)-ROW(ASCOPE_PMESII!$J$3)+1)/(ASCOPE_PMESII!$J$3:$J$62="CC"),1-(COUNTIF(ASCOPE_PMESII!$B$3:$B$62,"CC")+COUNTIF(ASCOPE_PMESII!$D$3:$D$62,"CC")+COUNTIF(ASCOPE_PMESII!$F$3:$F$62,"CC")+COUNTIF(ASCOPE_PMESII!$H$3:$H$62,"CC")))),""),IFERROR(INDEX(ASCOPE_PMESII!$M$3:$M$62,_xlfn.AGGREGATE(15,6,(ROW(ASCOPE_PMESII!$L$3:$L$62)-ROW(ASCOPE_PMESII!$L$3)+1)/(ASCOPE_PMESII!$L$3:$L$62="CC"),1-(COUNTIF(ASCOPE_PMESII!$B$3:$B$62,"CC")+COUNTIF(ASCOPE_PMESII!$D$3:$D$62,"CC")+COUNTIF(ASCOPE_PMESII!$F$3:$F$62,"CC")+COUNTIF(ASCOPE_PMESII!$H$3:$H$62,"CC")+COUNTIF(ASCOPE_PMESII!$J$3:$J$62,"CC")))),"")))))),"")} -> ACEH defence is political as well as military | Q4: {=IFERROR(IF(1<=COUNTIF(ASCOPE_PMESII!$B$3:$B$62,"CR"),IFERROR(INDEX(ASCOPE_PMESII!$C$3:$C$62,_xlfn.AGGREGATE(15,6,(ROW(ASCOPE_PMESII!$B$3:$B$62)-ROW(ASCOPE_PMESII!$B$3)+1)/(ASCOPE_PMESII!$B$3:$B$62="CR"),1)),""),IF(1<=(COUNTIF(ASCOPE_PMESII!$B$3:$B$62,"CR")+COUNTIF(ASCOPE_PMESII!$D$3:$D$62,"CR")),IFERROR(INDEX(ASCOPE_PMESII!$E$3:$E$62,_xlfn.AGGREGATE(15,6,(ROW(ASCOPE_PMESII!$D$3:$D$62)-ROW(ASCOPE_PMESII!$D$3)+1)/(ASCOPE_PMESII!$D$3:$D$62="CR"),1-(COUNTIF(ASCOPE_PMESII!$B$3:$B$62,"CR")))),""),IF(1<=(COUNTIF(ASCOPE_PMESII!$B$3:$B$62,"CR")+COUNTIF(ASCOPE_PMESII!$D$3:$D$62,"CR")+COUNTIF(ASCOPE_PMESII!$F$3:$F$62,"CR")),IFERROR(INDEX(ASCOPE_PMESII!$G$3:$G$62,_xlfn.AGGREGATE(15,6,(ROW(ASCOPE_PMESII!$F$3:$F$62)-ROW(ASCOPE_PMESII!$F$3)+1)/(ASCOPE_PMESII!$F$3:$F$62="CR"),1-(COUNTIF(ASCOPE_PMESII!$B$3:$B$62,"CR")+COUNTIF(ASCOPE_PMESII!$D$3:$D$62,"CR")))),""),IF(1<=(COUNTIF(ASCOPE_PMESII!$B$3:$B$62,"CR")+COUNTIF(ASCOPE_PMESII!$D$3:$D$62,"CR")+COUNTIF(ASCOPE_PMESII!$F$3:$F$62,"CR")+COUNTIF(ASCOPE_PMESII!$H$3:$H$62,"CR")),IFERROR(INDEX(ASCOPE_PMESII!$I$3:$I$62,_xlfn.AGGREGATE(15,6,(ROW(ASCOPE_PMESII!$H$3:$H$62)-ROW(ASCOPE_PMESII!$H$3)+1)/(ASCOPE_PMESII!$H$3:$H$62="CR"),1-(COUNTIF(ASCOPE_PMESII!$B$3:$B$62,"CR")+COUNTIF(ASCOPE_PMESII!$D$3:$D$62,"CR")+COUNTIF(ASCOPE_PMESII!$F$3:$F$62,"CR")))),""),IF(1<=(COUNTIF(ASCOPE_PMESII!$B$3:$B$62,"CR")+COUNTIF(ASCOPE_PMESII!$D$3:$D$62,"CR")+COUNTIF(ASCOPE_PMESII!$F$3:$F$62,"CR")+COUNTIF(ASCOPE_PMESII!$H$3:$H$62,"CR")+COUNTIF(ASCOPE_PMESII!$J$3:$J$62,"CR")),IFERROR(INDEX(ASCOPE_PMESII!$K$3:$K$62,_xlfn.AGGREGATE(15,6,(ROW(ASCOPE_PMESII!$J$3:$J$62)-ROW(ASCOPE_PMESII!$J$3)+1)/(ASCOPE_PMESII!$J$3:$J$62="CR"),1-(COUNTIF(ASCOPE_PMESII!$B$3:$B$62,"CR")+COUNTIF(ASCOPE_PMESII!$D$3:$D$62,"CR")+COUNTIF(ASCOPE_PMESII!$F$3:$F$62,"CR")+COUNTIF(ASCOPE_PMESII!$H$3:$H$62,"CR")))),""),IFERROR(INDEX(ASCOPE_PMESII!$M$3:$M$62,_xlfn.AGGREGATE(15,6,(ROW(ASCOPE_PMESII!$L$3:$L$62)-ROW(ASCOPE_PMESII!$L$3)+1)/(ASCOPE_PMESII!$L$3:$L$62="CR"),1-(COUNTIF(ASCOPE_PMESII!$B$3:$B$62,"CR")+COUNTIF(ASCOPE_PMESII!$D$3:$D$62,"CR")+COUNTIF(ASCOPE_PMESII!$F$3:$F$62,"CR")+COUNTIF(ASCOPE_PMESII!$H$3:$H$62,"CR")+COUNTIF(ASCOPE_PMESII!$J$3:$J$62,"CR")))),"")))))),"")} -> GoIND consent enables NATO legitimacy | R4: {=IFERROR(IF(1<=COUNTIF(ASCOPE_PMESII!$B$3:$B$62,"PCS"),IFERROR(INDEX(ASCOPE_PMESII!$C$3:$C$62,_xlfn.AGGREGATE(15,6,(ROW(ASCOPE_PMESII!$B$3:$B$62)-ROW(ASCOPE_PMESII!$B$3)+1)/(ASCOPE_PMESII!$B$3:$B$62="PCS"),1)),""),IF(1<=(COUNTIF(ASCOPE_PMESII!$B$3:$B$62,"PCS")+COUNTIF(ASCOPE_PMESII!$D$3:$D$62,"PCS")),IFERROR(INDEX(ASCOPE_PMESII!$E$3:$E$62,_xlfn.AGGREGATE(15,6,(ROW(ASCOPE_PMESII!$D$3:$D$62)-ROW(ASCOPE_PMESII!$D$3)+1)/(ASCOPE_PMESII!$D$3:$D$62="PCS"),1-(COUNTIF(ASCOPE_PMESII!$B$3:$B$62,"PCS")))),""),IF(1<=(COUNTIF(ASCOPE_PMESII!$B$3:$B$62,"PCS")+COUNTIF(ASCOPE_PMESII!$D$3:$D$62,"PCS")+COUNTIF(ASCOPE_PMESII!$F$3:$F$62,"PCS")),IFERROR(INDEX(ASCOPE_PMESII!$G$3:$G$62,_xlfn.AGGREGATE(15,6,(ROW(ASCOPE_PMESII!$F$3:$F$62)-ROW(ASCOPE_PMESII!$F$3)+1)/(ASCOPE_PMESII!$F$3:$F$62="PCS"),1-(COUNTIF(ASCOPE_PMESII!$B$3:$B$62,"PCS")+COUNTIF(ASCOPE_PMESII!$D$3:$D$62,"PCS")))),""),IF(1<=(COUNTIF(ASCOPE_PMESII!$B$3:$B$62,"PCS")+COUNTIF(ASCOPE_PMESII!$D$3:$D$62,"PCS")+COUNTIF(ASCOPE_PMESII!$F$3:$F$62,"PCS")+COUNTIF(ASCOPE_PMESII!$H$3:$H$62,"PCS")),IFERROR(INDEX(ASCOPE_PMESII!$I$3:$I$62,_xlfn.AGGREGATE(15,6,(ROW(ASCOPE_PMESII!$H$3:$H$62)-ROW(ASCOPE_PMESII!$H$3)+1)/(ASCOPE_PMESII!$H$3:$H$62="PCS"),1-(COUNTIF(ASCOPE_PMESII!$B$3:$B$62,"PCS")+COUNTIF(ASCOPE_PMESII!$D$3:$D$62,"PCS")+COUNTIF(ASCOPE_PMESII!$F$3:$F$62,"PCS")))),""),IF(1<=(COUNTIF(ASCOPE_PMESII!$B$3:$B$62,"PCS")+COUNTIF(ASCOPE_PMESII!$D$3:$D$62,"PCS")+COUNTIF(ASCOPE_PMESII!$F$3:$F$62,"PCS")+COUNTIF(ASCOPE_PMESII!$H$3:$H$62,"PCS")+COUNTIF(ASCOPE_PMESII!$J$3:$J$62,"PCS")),IFERROR(INDEX(ASCOPE_PMESII!$K$3:$K$62,_xlfn.AGGREGATE(15,6,(ROW(ASCOPE_PMESII!$J$3:$J$62)-ROW(ASCOPE_PMESII!$J$3)+1)/(ASCOPE_PMESII!$J$3:$J$62="PCS"),1-(COUNTIF(ASCOPE_PMESII!$B$3:$B$62,"PCS")+COUNTIF(ASCOPE_PMESII!$D$3:$D$62,"PCS")+COUNTIF(ASCOPE_PMESII!$F$3:$F$62,"PCS")+COUNTIF(ASCOPE_PMESII!$H$3:$H$62,"PCS")))),""),IFERROR(INDEX(ASCOPE_PMESII!$M$3:$M$62,_xlfn.AGGREGATE(15,6,(ROW(ASCOPE_PMESII!$L$3:$L$62)-ROW(ASCOPE_PMESII!$L$3)+1)/(ASCOPE_PMESII!$L$3:$L$62="PCS"),1-(COUNTIF(ASCOPE_PMESII!$B$3:$B$62,"PCS")+COUNTIF(ASCOPE_PMESII!$D$3:$D$62,"PCS")+COUNTIF(ASCOPE_PMESII!$F$3:$F$62,"PCS")+COUNTIF(ASCOPE_PMESII!$H$3:$H$62,"PCS")+COUNTIF(ASCOPE_PMESII!$J$3:$J$62,"PCS")))),"")))))),"")}
